{
 "cells": [
  {
   "cell_type": "markdown",
   "metadata": {},
   "source": [
    "# MolMap to CYP450 dataset (dual-path approach)"
   ]
  },
  {
   "cell_type": "code",
   "execution_count": null,
   "metadata": {},
   "outputs": [],
   "source": [
    "import os\n",
    "os.environ[\"CUDA_DEVICE_ORDER\"]=\"PCI_BUS_ID\"\n",
    "os.environ[\"CUDA_VISIBLE_DEVICES\"]='0'\n",
    "\n",
    "import tensorflow as tf\n",
    "\n",
    "physical_devices = tf.config.experimental.list_physical_devices('GPU')\n",
    "tf.config.experimental.set_memory_growth(physical_devices[0], True)"
   ]
  },
  {
   "cell_type": "markdown",
   "metadata": {},
   "source": [
    "### Load data"
   ]
  },
  {
   "cell_type": "code",
   "execution_count": 1,
   "metadata": {},
   "outputs": [],
   "source": [
    "import numpy as np\n",
    "import pandas as pd\n",
    "\n",
    "# read data CYP\n",
    "data = pd.read_csv(\"../../../data/CYP450.csv.gz\", compression='gzip')"
   ]
  },
  {
   "cell_type": "markdown",
   "metadata": {},
   "source": [
    "Set up"
   ]
  },
  {
   "cell_type": "code",
   "execution_count": 2,
   "metadata": {},
   "outputs": [
    {
     "name": "stdout",
     "output_type": "stream",
     "text": [
      "Inactive (0): 7429\n",
      "Active (1): 2621\n"
     ]
    }
   ],
   "source": [
    "# keep desired columns\n",
    "data = data[['smiles', 'label_2c9']]\n",
    "\n",
    "# drop molecules with NaN activity\n",
    "data = data.dropna(subset = [\"label_2c9\"])\n",
    "\n",
    "# set smiles\n",
    "smi = data['smiles']\n",
    "\n",
    "# set Y\n",
    "Y = pd.get_dummies(data['label_2c9']).values\n",
    "\n",
    "# number of active and inactive molecules\n",
    "print(\"Inactive (0):\", Y[:,1].tolist().count(0))\n",
    "print(\"Active (1):\", Y[:,1].tolist().count(1))"
   ]
  },
  {
   "cell_type": "markdown",
   "metadata": {},
   "source": [
    "### Do MolMap: from MolDs & FFs to Fmaps"
   ]
  },
  {
   "cell_type": "code",
   "execution_count": 3,
   "metadata": {},
   "outputs": [],
   "source": [
    "import pickle\n",
    "from pathlib import Path\n",
    "from molmap import MolMap\n",
    "from molmap import feature\n",
    "\n",
    "X1_file = Path(\"../../../files/CYP450/molmap/X1.data\")\n",
    "X2_file = Path(\"../../../files/CYP450/molmap/X2.data\")\n",
    "\n",
    "if X1_file.is_file() and X2_file.is_file():\n",
    "    'If it exists, we load it.'\n",
    "    with open(X1_file, \"rb\") as f:\n",
    "        X1 = pickle.load(f)\n",
    "    with open(X2_file, \"rb\") as f:\n",
    "        X2 = pickle.load(f)\n",
    "\n",
    "else: \n",
    "    'Otherwise, we compute it and save it to disk.'\n",
    "    # compute MolDs\n",
    "    mp1 = MolMap(ftype='descriptor', metric='cosine',)\n",
    "    mp1.fit(verbose=0, method='umap', min_dist=0.1, n_neighbors=15,)\n",
    "    \n",
    "    # compute FFs\n",
    "    bitsinfo = feature.fingerprint.Extraction().bitsinfo\n",
    "    flist = bitsinfo[bitsinfo.Subtypes.isin(['PubChemFP', 'MACCSFP', 'PharmacoErGFP'])].IDs.tolist()\n",
    "    mp2 = MolMap(ftype = 'fingerprint', fmap_type = 'scatter', flist = flist) \n",
    "    mp2.fit(method = 'umap',  min_dist = 0.1, n_neighbors = 15, verbose = 0)\n",
    "\n",
    "    # get Fmaps\n",
    "    X1 = mp1.batch_transform(smi)\n",
    "    X2 = mp2.batch_transform(smi)\n",
    "\n",
    "    # save in disk\n",
    "    with open(X1_file, \"wb+\") as f:\n",
    "        pickle.dump(X1, f, pickle.HIGHEST_PROTOCOL)\n",
    "    with open(X2_file, \"wb+\") as f:\n",
    "        pickle.dump(X2, f, pickle.HIGHEST_PROTOCOL)"
   ]
  },
  {
   "cell_type": "markdown",
   "metadata": {},
   "source": [
    "### Split train, validation and test"
   ]
  },
  {
   "cell_type": "code",
   "execution_count": 4,
   "metadata": {},
   "outputs": [
    {
     "name": "stdout",
     "output_type": "stream",
     "text": [
      "8040 1005 1005\n"
     ]
    }
   ],
   "source": [
    "import sys\n",
    "sys.path.append(\"../../../src\")\n",
    "from utils import Rdsplit\n",
    "\n",
    "train_idx, valid_idx, test_idx = Rdsplit(data, random_state = 888)"
   ]
  },
  {
   "cell_type": "code",
   "execution_count": 5,
   "metadata": {},
   "outputs": [],
   "source": [
    "trainX = (X1[train_idx], X2[train_idx])\n",
    "validX = (X1[valid_idx], X2[valid_idx])\n",
    "testX = (X1[test_idx], X2[test_idx])\n",
    "\n",
    "trainY = Y[train_idx]\n",
    "validY = Y[valid_idx]\n",
    "testY = Y[test_idx]"
   ]
  },
  {
   "cell_type": "markdown",
   "metadata": {},
   "source": [
    "### Build MolMapNet model (MultiClassEstimator)"
   ]
  },
  {
   "cell_type": "code",
   "execution_count": 6,
   "metadata": {},
   "outputs": [
    {
     "name": "stdout",
     "output_type": "stream",
     "text": [
      "MultiClassEstimator(epochs=100, fmap_shape1=(37, 37, 13),\n",
      "                    fmap_shape2=(72, 72, 3), gpuid='0', n_outputs=2)\n"
     ]
    }
   ],
   "source": [
    "from molmap.model import MultiClassEstimator\n",
    "\n",
    "clf = MultiClassEstimator(n_outputs=trainY.shape[1], \n",
    "                          fmap_shape1 = X1.shape[1:],\n",
    "                          fmap_shape2 = X2.shape[1:],\n",
    "                          metric='ROC', \n",
    "                          dense_layers = [128, 64], gpuid = 0, epochs = 100) "
   ]
  },
  {
   "cell_type": "markdown",
   "metadata": {},
   "source": [
    "### Train model"
   ]
  },
  {
   "cell_type": "code",
   "execution_count": null,
   "metadata": {},
   "outputs": [
    {
     "name": "stdout",
     "output_type": "stream",
     "text": [
      "WARNING: Entity <function Function._initialize_uninitialized_variables.<locals>.initialize_variables at 0x7fd4ac12a8c8> could not be transformed and will be executed as-is. Please report this to the AutoGraph team. When filing the bug, set the verbosity to 10 (on Linux, `export AUTOGRAPH_VERBOSITY=10`) and attach the full output. Cause: No module named 'tensorflow_core.estimator'\n"
     ]
    },
    {
     "name": "stderr",
     "output_type": "stream",
     "text": [
      "ERROR:root:Internal Python error in the inspect module.\n",
      "Below is the traceback from this internal error.\n",
      "\n",
      "ERROR:root:Internal Python error in the inspect module.\n",
      "Below is the traceback from this internal error.\n",
      "\n",
      "ERROR:root:Internal Python error in the inspect module.\n",
      "Below is the traceback from this internal error.\n",
      "\n"
     ]
    },
    {
     "name": "stdout",
     "output_type": "stream",
     "text": [
      "Traceback (most recent call last):\n",
      "  File \"/home/hodei/anaconda3/envs/molmap/lib/python3.6/site-packages/tensorflow_core/python/keras/engine/training_v2.py\", line 668, in on_start\n",
      "    yield\n",
      "  File \"/home/hodei/anaconda3/envs/molmap/lib/python3.6/site-packages/tensorflow_core/python/keras/engine/training_v2.py\", line 372, in fit\n",
      "    prefix='val_')\n",
      "  File \"/home/hodei/anaconda3/envs/molmap/lib/python3.6/contextlib.py\", line 99, in __exit__\n",
      "    self.gen.throw(type, value, traceback)\n",
      "  File \"/home/hodei/anaconda3/envs/molmap/lib/python3.6/site-packages/tensorflow_core/python/keras/engine/training_v2.py\", line 685, in on_epoch\n",
      "    self.callbacks.on_epoch_end(epoch, epoch_logs)\n",
      "  File \"/home/hodei/anaconda3/envs/molmap/lib/python3.6/site-packages/tensorflow_core/python/keras/callbacks.py\", line 298, in on_epoch_end\n",
      "    callback.on_epoch_end(epoch, logs)\n",
      "  File \"/home/nuriacami/Documents/bidd-molmap/molmap/model/cbks2.py\", line 286, in on_epoch_end\n",
      "    y_pred = self.model.predict(self.x)\n",
      "  File \"/home/hodei/anaconda3/envs/molmap/lib/python3.6/site-packages/tensorflow_core/python/keras/engine/training.py\", line 909, in predict\n",
      "    use_multiprocessing=use_multiprocessing)\n",
      "  File \"/home/hodei/anaconda3/envs/molmap/lib/python3.6/site-packages/tensorflow_core/python/keras/engine/training_v2.py\", line 462, in predict\n",
      "    steps=steps, callbacks=callbacks, **kwargs)\n",
      "  File \"/home/hodei/anaconda3/envs/molmap/lib/python3.6/site-packages/tensorflow_core/python/keras/engine/training_v2.py\", line 444, in _model_iteration\n",
      "    total_epochs=1)\n",
      "  File \"/home/hodei/anaconda3/envs/molmap/lib/python3.6/site-packages/tensorflow_core/python/keras/engine/training_v2.py\", line 123, in run_one_epoch\n",
      "    batch_outs = execution_function(iterator)\n",
      "  File \"/home/hodei/anaconda3/envs/molmap/lib/python3.6/site-packages/tensorflow_core/python/keras/engine/training_v2_utils.py\", line 86, in execution_function\n",
      "    distributed_function(input_fn))\n",
      "  File \"/home/hodei/anaconda3/envs/molmap/lib/python3.6/site-packages/tensorflow_core/python/eager/def_function.py\", line 457, in __call__\n",
      "    result = self._call(*args, **kwds)\n",
      "  File \"/home/hodei/anaconda3/envs/molmap/lib/python3.6/site-packages/tensorflow_core/python/eager/def_function.py\", line 526, in _call\n",
      "    return self._concrete_stateful_fn._filtered_call(canon_args, canon_kwds)  # pylint: disable=protected-access\n",
      "  File \"/home/hodei/anaconda3/envs/molmap/lib/python3.6/site-packages/tensorflow_core/python/eager/function.py\", line 1141, in _filtered_call\n",
      "    self.captured_inputs)\n",
      "  File \"/home/hodei/anaconda3/envs/molmap/lib/python3.6/site-packages/tensorflow_core/python/eager/function.py\", line 1224, in _call_flat\n",
      "    ctx, args, cancellation_manager=cancellation_manager)\n",
      "  File \"/home/hodei/anaconda3/envs/molmap/lib/python3.6/site-packages/tensorflow_core/python/eager/function.py\", line 511, in call\n",
      "    ctx=ctx)\n",
      "  File \"/home/hodei/anaconda3/envs/molmap/lib/python3.6/site-packages/tensorflow_core/python/eager/execute.py\", line 67, in quick_execute\n",
      "    six.raise_from(core._status_to_exception(e.code, message), None)\n",
      "  File \"<string>\", line 3, in raise_from\n",
      "tensorflow.python.framework.errors_impl.UnknownError:  Failed to get convolution algorithm. This is probably because cuDNN failed to initialize, so try looking to see if a warning log message was printed above.\n",
      "\t [[node model/conv2d/Conv2D (defined at /home/hodei/anaconda3/envs/molmap/lib/python3.6/site-packages/tensorflow_core/python/framework/ops.py:1751) ]] [Op:__inference_distributed_function_2875]\n",
      "\n",
      "Function call stack:\n",
      "distributed_function\n",
      "\n",
      "\n",
      "During handling of the above exception, another exception occurred:\n",
      "\n",
      "Traceback (most recent call last):\n",
      "  File \"/home/hodei/anaconda3/envs/molmap/lib/python3.6/site-packages/IPython/core/interactiveshell.py\", line 3343, in run_code\n",
      "    exec(code_obj, self.user_global_ns, self.user_ns)\n",
      "  File \"<ipython-input-7-9b2d8a865dc9>\", line 1, in <module>\n",
      "    clf.fit(trainX, trainY, validX, validY)\n",
      "  File \"/home/nuriacami/Documents/bidd-molmap/molmap/model/model.py\", line 481, in fit\n",
      "    callbacks=[performance])\n",
      "  File \"/home/hodei/anaconda3/envs/molmap/lib/python3.6/site-packages/tensorflow_core/python/keras/engine/training.py\", line 728, in fit\n",
      "    use_multiprocessing=use_multiprocessing)\n",
      "  File \"/home/hodei/anaconda3/envs/molmap/lib/python3.6/site-packages/tensorflow_core/python/keras/engine/training_v2.py\", line 372, in fit\n",
      "    prefix='val_')\n",
      "  File \"/home/hodei/anaconda3/envs/molmap/lib/python3.6/contextlib.py\", line 99, in __exit__\n",
      "    self.gen.throw(type, value, traceback)\n",
      "  File \"/home/hodei/anaconda3/envs/molmap/lib/python3.6/site-packages/tensorflow_core/python/keras/engine/training_v2.py\", line 671, in on_start\n",
      "    self.callbacks._call_end_hook(mode)\n",
      "  File \"/home/hodei/anaconda3/envs/molmap/lib/python3.6/site-packages/tensorflow_core/python/keras/callbacks.py\", line 258, in _call_end_hook\n",
      "    self.on_train_end()\n",
      "  File \"/home/hodei/anaconda3/envs/molmap/lib/python3.6/site-packages/tensorflow_core/python/keras/callbacks.py\", line 375, in on_train_end\n",
      "    callback.on_train_end(logs)\n",
      "  File \"/home/nuriacami/Documents/bidd-molmap/molmap/model/cbks2.py\", line 358, in on_train_end\n",
      "    self.model.set_weights(self.best_weights)\n",
      "  File \"/home/hodei/anaconda3/envs/molmap/lib/python3.6/site-packages/tensorflow_core/python/keras/engine/base_layer.py\", line 1322, in set_weights\n",
      "    if len(params) != len(weights):\n",
      "TypeError: object of type 'NoneType' has no len()\n",
      "\n",
      "During handling of the above exception, another exception occurred:\n",
      "\n",
      "Traceback (most recent call last):\n",
      "  File \"/home/hodei/anaconda3/envs/molmap/lib/python3.6/site-packages/IPython/core/interactiveshell.py\", line 2044, in showtraceback\n",
      "    stb = value._render_traceback_()\n",
      "AttributeError: 'TypeError' object has no attribute '_render_traceback_'\n",
      "\n",
      "During handling of the above exception, another exception occurred:\n",
      "\n",
      "Traceback (most recent call last):\n",
      "  File \"/home/hodei/anaconda3/envs/molmap/lib/python3.6/site-packages/IPython/core/ultratb.py\", line 1169, in get_records\n",
      "    return _fixed_getinnerframes(etb, number_of_lines_of_context, tb_offset)\n",
      "  File \"/home/hodei/anaconda3/envs/molmap/lib/python3.6/site-packages/IPython/core/ultratb.py\", line 316, in wrapped\n",
      "    return f(*args, **kwargs)\n",
      "  File \"/home/hodei/anaconda3/envs/molmap/lib/python3.6/site-packages/IPython/core/ultratb.py\", line 350, in _fixed_getinnerframes\n",
      "    records = fix_frame_records_filenames(inspect.getinnerframes(etb, context))\n",
      "  File \"/home/hodei/anaconda3/envs/molmap/lib/python3.6/inspect.py\", line 1490, in getinnerframes\n",
      "    frameinfo = (tb.tb_frame,) + getframeinfo(tb, context)\n",
      "  File \"/home/hodei/anaconda3/envs/molmap/lib/python3.6/inspect.py\", line 1448, in getframeinfo\n",
      "    filename = getsourcefile(frame) or getfile(frame)\n",
      "  File \"/home/hodei/anaconda3/envs/molmap/lib/python3.6/inspect.py\", line 696, in getsourcefile\n",
      "    if getattr(getmodule(object, filename), '__loader__', None) is not None:\n",
      "  File \"/home/hodei/anaconda3/envs/molmap/lib/python3.6/inspect.py\", line 733, in getmodule\n",
      "    if ismodule(module) and hasattr(module, '__file__'):\n",
      "  File \"/home/hodei/anaconda3/envs/molmap/lib/python3.6/site-packages/tensorflow/__init__.py\", line 50, in __getattr__\n",
      "    module = self._load()\n",
      "  File \"/home/hodei/anaconda3/envs/molmap/lib/python3.6/site-packages/tensorflow/__init__.py\", line 44, in _load\n",
      "    module = _importlib.import_module(self.__name__)\n",
      "  File \"/home/hodei/anaconda3/envs/molmap/lib/python3.6/importlib/__init__.py\", line 126, in import_module\n",
      "    return _bootstrap._gcd_import(name[level:], package, level)\n",
      "  File \"<frozen importlib._bootstrap>\", line 994, in _gcd_import\n",
      "  File \"<frozen importlib._bootstrap>\", line 971, in _find_and_load\n",
      "  File \"<frozen importlib._bootstrap>\", line 953, in _find_and_load_unlocked\n",
      "ModuleNotFoundError: No module named 'tensorflow_core.estimator'\n",
      "Traceback (most recent call last):\n",
      "  File \"/home/hodei/anaconda3/envs/molmap/lib/python3.6/site-packages/tensorflow_core/python/keras/engine/training_v2.py\", line 668, in on_start\n",
      "    yield\n",
      "  File \"/home/hodei/anaconda3/envs/molmap/lib/python3.6/site-packages/tensorflow_core/python/keras/engine/training_v2.py\", line 372, in fit\n",
      "    prefix='val_')\n",
      "  File \"/home/hodei/anaconda3/envs/molmap/lib/python3.6/contextlib.py\", line 99, in __exit__\n",
      "    self.gen.throw(type, value, traceback)\n",
      "  File \"/home/hodei/anaconda3/envs/molmap/lib/python3.6/site-packages/tensorflow_core/python/keras/engine/training_v2.py\", line 685, in on_epoch\n",
      "    self.callbacks.on_epoch_end(epoch, epoch_logs)\n",
      "  File \"/home/hodei/anaconda3/envs/molmap/lib/python3.6/site-packages/tensorflow_core/python/keras/callbacks.py\", line 298, in on_epoch_end\n",
      "    callback.on_epoch_end(epoch, logs)\n",
      "  File \"/home/nuriacami/Documents/bidd-molmap/molmap/model/cbks2.py\", line 286, in on_epoch_end\n",
      "    y_pred = self.model.predict(self.x)\n",
      "  File \"/home/hodei/anaconda3/envs/molmap/lib/python3.6/site-packages/tensorflow_core/python/keras/engine/training.py\", line 909, in predict\n",
      "    use_multiprocessing=use_multiprocessing)\n",
      "  File \"/home/hodei/anaconda3/envs/molmap/lib/python3.6/site-packages/tensorflow_core/python/keras/engine/training_v2.py\", line 462, in predict\n",
      "    steps=steps, callbacks=callbacks, **kwargs)\n",
      "  File \"/home/hodei/anaconda3/envs/molmap/lib/python3.6/site-packages/tensorflow_core/python/keras/engine/training_v2.py\", line 444, in _model_iteration\n",
      "    total_epochs=1)\n",
      "  File \"/home/hodei/anaconda3/envs/molmap/lib/python3.6/site-packages/tensorflow_core/python/keras/engine/training_v2.py\", line 123, in run_one_epoch\n",
      "    batch_outs = execution_function(iterator)\n",
      "  File \"/home/hodei/anaconda3/envs/molmap/lib/python3.6/site-packages/tensorflow_core/python/keras/engine/training_v2_utils.py\", line 86, in execution_function\n",
      "    distributed_function(input_fn))\n",
      "  File \"/home/hodei/anaconda3/envs/molmap/lib/python3.6/site-packages/tensorflow_core/python/eager/def_function.py\", line 457, in __call__\n",
      "    result = self._call(*args, **kwds)\n",
      "  File \"/home/hodei/anaconda3/envs/molmap/lib/python3.6/site-packages/tensorflow_core/python/eager/def_function.py\", line 526, in _call\n",
      "    return self._concrete_stateful_fn._filtered_call(canon_args, canon_kwds)  # pylint: disable=protected-access\n",
      "  File \"/home/hodei/anaconda3/envs/molmap/lib/python3.6/site-packages/tensorflow_core/python/eager/function.py\", line 1141, in _filtered_call\n",
      "    self.captured_inputs)\n",
      "  File \"/home/hodei/anaconda3/envs/molmap/lib/python3.6/site-packages/tensorflow_core/python/eager/function.py\", line 1224, in _call_flat\n",
      "    ctx, args, cancellation_manager=cancellation_manager)\n",
      "  File \"/home/hodei/anaconda3/envs/molmap/lib/python3.6/site-packages/tensorflow_core/python/eager/function.py\", line 511, in call\n",
      "    ctx=ctx)\n",
      "  File \"/home/hodei/anaconda3/envs/molmap/lib/python3.6/site-packages/tensorflow_core/python/eager/execute.py\", line 67, in quick_execute\n",
      "    six.raise_from(core._status_to_exception(e.code, message), None)\n",
      "  File \"<string>\", line 3, in raise_from\n",
      "tensorflow.python.framework.errors_impl.UnknownError:  Failed to get convolution algorithm. This is probably because cuDNN failed to initialize, so try looking to see if a warning log message was printed above.\n",
      "\t [[node model/conv2d/Conv2D (defined at /home/hodei/anaconda3/envs/molmap/lib/python3.6/site-packages/tensorflow_core/python/framework/ops.py:1751) ]] [Op:__inference_distributed_function_2875]\n",
      "\n",
      "Function call stack:\n",
      "distributed_function\n",
      "\n",
      "\n",
      "During handling of the above exception, another exception occurred:\n",
      "\n",
      "Traceback (most recent call last):\n",
      "  File \"/home/hodei/anaconda3/envs/molmap/lib/python3.6/site-packages/IPython/core/interactiveshell.py\", line 3343, in run_code\n",
      "    exec(code_obj, self.user_global_ns, self.user_ns)\n",
      "  File \"<ipython-input-7-9b2d8a865dc9>\", line 1, in <module>\n",
      "    clf.fit(trainX, trainY, validX, validY)\n",
      "  File \"/home/nuriacami/Documents/bidd-molmap/molmap/model/model.py\", line 481, in fit\n",
      "    callbacks=[performance])\n",
      "  File \"/home/hodei/anaconda3/envs/molmap/lib/python3.6/site-packages/tensorflow_core/python/keras/engine/training.py\", line 728, in fit\n",
      "    use_multiprocessing=use_multiprocessing)\n",
      "  File \"/home/hodei/anaconda3/envs/molmap/lib/python3.6/site-packages/tensorflow_core/python/keras/engine/training_v2.py\", line 372, in fit\n",
      "    prefix='val_')\n",
      "  File \"/home/hodei/anaconda3/envs/molmap/lib/python3.6/contextlib.py\", line 99, in __exit__\n",
      "    self.gen.throw(type, value, traceback)\n",
      "  File \"/home/hodei/anaconda3/envs/molmap/lib/python3.6/site-packages/tensorflow_core/python/keras/engine/training_v2.py\", line 671, in on_start\n",
      "    self.callbacks._call_end_hook(mode)\n",
      "  File \"/home/hodei/anaconda3/envs/molmap/lib/python3.6/site-packages/tensorflow_core/python/keras/callbacks.py\", line 258, in _call_end_hook\n",
      "    self.on_train_end()\n",
      "  File \"/home/hodei/anaconda3/envs/molmap/lib/python3.6/site-packages/tensorflow_core/python/keras/callbacks.py\", line 375, in on_train_end\n",
      "    callback.on_train_end(logs)\n",
      "  File \"/home/nuriacami/Documents/bidd-molmap/molmap/model/cbks2.py\", line 358, in on_train_end\n",
      "    self.model.set_weights(self.best_weights)\n",
      "  File \"/home/hodei/anaconda3/envs/molmap/lib/python3.6/site-packages/tensorflow_core/python/keras/engine/base_layer.py\", line 1322, in set_weights\n",
      "    if len(params) != len(weights):\n",
      "TypeError: object of type 'NoneType' has no len()\n",
      "\n",
      "During handling of the above exception, another exception occurred:\n",
      "\n",
      "Traceback (most recent call last):\n",
      "  File \"/home/hodei/anaconda3/envs/molmap/lib/python3.6/site-packages/IPython/core/interactiveshell.py\", line 2044, in showtraceback\n",
      "    stb = value._render_traceback_()\n",
      "AttributeError: 'TypeError' object has no attribute '_render_traceback_'\n",
      "\n",
      "During handling of the above exception, another exception occurred:\n",
      "\n",
      "Traceback (most recent call last):\n",
      "  File \"/home/hodei/anaconda3/envs/molmap/lib/python3.6/site-packages/IPython/core/interactiveshell.py\", line 3263, in run_ast_nodes\n",
      "    if (await self.run_code(code, result,  async_=asy)):\n",
      "  File \"/home/hodei/anaconda3/envs/molmap/lib/python3.6/site-packages/IPython/core/interactiveshell.py\", line 3360, in run_code\n",
      "    self.showtraceback(running_compiled_code=True)\n",
      "  File \"/home/hodei/anaconda3/envs/molmap/lib/python3.6/site-packages/IPython/core/interactiveshell.py\", line 2047, in showtraceback\n",
      "    value, tb, tb_offset=tb_offset)\n",
      "  File \"/home/hodei/anaconda3/envs/molmap/lib/python3.6/site-packages/IPython/core/ultratb.py\", line 1436, in structured_traceback\n",
      "    self, etype, value, tb, tb_offset, number_of_lines_of_context)\n",
      "  File \"/home/hodei/anaconda3/envs/molmap/lib/python3.6/site-packages/IPython/core/ultratb.py\", line 1336, in structured_traceback\n",
      "    self, etype, value, tb, tb_offset, number_of_lines_of_context\n",
      "  File \"/home/hodei/anaconda3/envs/molmap/lib/python3.6/site-packages/IPython/core/ultratb.py\", line 1193, in structured_traceback\n",
      "    tb_offset)\n",
      "  File \"/home/hodei/anaconda3/envs/molmap/lib/python3.6/site-packages/IPython/core/ultratb.py\", line 1150, in format_exception_as_a_whole\n",
      "    last_unique, recursion_repeat = find_recursion(orig_etype, evalue, records)\n",
      "  File \"/home/hodei/anaconda3/envs/molmap/lib/python3.6/site-packages/IPython/core/ultratb.py\", line 451, in find_recursion\n",
      "    return len(records), 0\n",
      "TypeError: object of type 'NoneType' has no len()\n",
      "\n",
      "During handling of the above exception, another exception occurred:\n",
      "\n",
      "Traceback (most recent call last):\n",
      "  File \"/home/hodei/anaconda3/envs/molmap/lib/python3.6/site-packages/IPython/core/interactiveshell.py\", line 2044, in showtraceback\n",
      "    stb = value._render_traceback_()\n",
      "AttributeError: 'TypeError' object has no attribute '_render_traceback_'\n",
      "\n",
      "During handling of the above exception, another exception occurred:\n",
      "\n",
      "Traceback (most recent call last):\n",
      "  File \"/home/hodei/anaconda3/envs/molmap/lib/python3.6/site-packages/IPython/core/ultratb.py\", line 1169, in get_records\n",
      "    return _fixed_getinnerframes(etb, number_of_lines_of_context, tb_offset)\n",
      "  File \"/home/hodei/anaconda3/envs/molmap/lib/python3.6/site-packages/IPython/core/ultratb.py\", line 316, in wrapped\n",
      "    return f(*args, **kwargs)\n",
      "  File \"/home/hodei/anaconda3/envs/molmap/lib/python3.6/site-packages/IPython/core/ultratb.py\", line 350, in _fixed_getinnerframes\n",
      "    records = fix_frame_records_filenames(inspect.getinnerframes(etb, context))\n",
      "  File \"/home/hodei/anaconda3/envs/molmap/lib/python3.6/inspect.py\", line 1490, in getinnerframes\n",
      "    frameinfo = (tb.tb_frame,) + getframeinfo(tb, context)\n",
      "  File \"/home/hodei/anaconda3/envs/molmap/lib/python3.6/inspect.py\", line 1448, in getframeinfo\n",
      "    filename = getsourcefile(frame) or getfile(frame)\n",
      "  File \"/home/hodei/anaconda3/envs/molmap/lib/python3.6/inspect.py\", line 696, in getsourcefile\n",
      "    if getattr(getmodule(object, filename), '__loader__', None) is not None:\n",
      "  File \"/home/hodei/anaconda3/envs/molmap/lib/python3.6/inspect.py\", line 733, in getmodule\n",
      "    if ismodule(module) and hasattr(module, '__file__'):\n",
      "  File \"/home/hodei/anaconda3/envs/molmap/lib/python3.6/site-packages/tensorflow/__init__.py\", line 50, in __getattr__\n",
      "    module = self._load()\n",
      "  File \"/home/hodei/anaconda3/envs/molmap/lib/python3.6/site-packages/tensorflow/__init__.py\", line 44, in _load\n",
      "    module = _importlib.import_module(self.__name__)\n",
      "  File \"/home/hodei/anaconda3/envs/molmap/lib/python3.6/importlib/__init__.py\", line 126, in import_module\n",
      "    return _bootstrap._gcd_import(name[level:], package, level)\n",
      "  File \"<frozen importlib._bootstrap>\", line 994, in _gcd_import\n",
      "  File \"<frozen importlib._bootstrap>\", line 971, in _find_and_load\n",
      "  File \"<frozen importlib._bootstrap>\", line 953, in _find_and_load_unlocked\n",
      "ModuleNotFoundError: No module named 'tensorflow_core.estimator'\n",
      "Traceback (most recent call last):\n",
      "  File \"/home/hodei/anaconda3/envs/molmap/lib/python3.6/site-packages/tensorflow_core/python/keras/engine/training_v2.py\", line 668, in on_start\n",
      "    yield\n",
      "  File \"/home/hodei/anaconda3/envs/molmap/lib/python3.6/site-packages/tensorflow_core/python/keras/engine/training_v2.py\", line 372, in fit\n",
      "    prefix='val_')\n",
      "  File \"/home/hodei/anaconda3/envs/molmap/lib/python3.6/contextlib.py\", line 99, in __exit__\n",
      "    self.gen.throw(type, value, traceback)\n",
      "  File \"/home/hodei/anaconda3/envs/molmap/lib/python3.6/site-packages/tensorflow_core/python/keras/engine/training_v2.py\", line 685, in on_epoch\n",
      "    self.callbacks.on_epoch_end(epoch, epoch_logs)\n",
      "  File \"/home/hodei/anaconda3/envs/molmap/lib/python3.6/site-packages/tensorflow_core/python/keras/callbacks.py\", line 298, in on_epoch_end\n",
      "    callback.on_epoch_end(epoch, logs)\n",
      "  File \"/home/nuriacami/Documents/bidd-molmap/molmap/model/cbks2.py\", line 286, in on_epoch_end\n",
      "    y_pred = self.model.predict(self.x)\n",
      "  File \"/home/hodei/anaconda3/envs/molmap/lib/python3.6/site-packages/tensorflow_core/python/keras/engine/training.py\", line 909, in predict\n",
      "    use_multiprocessing=use_multiprocessing)\n",
      "  File \"/home/hodei/anaconda3/envs/molmap/lib/python3.6/site-packages/tensorflow_core/python/keras/engine/training_v2.py\", line 462, in predict\n",
      "    steps=steps, callbacks=callbacks, **kwargs)\n",
      "  File \"/home/hodei/anaconda3/envs/molmap/lib/python3.6/site-packages/tensorflow_core/python/keras/engine/training_v2.py\", line 444, in _model_iteration\n",
      "    total_epochs=1)\n",
      "  File \"/home/hodei/anaconda3/envs/molmap/lib/python3.6/site-packages/tensorflow_core/python/keras/engine/training_v2.py\", line 123, in run_one_epoch\n",
      "    batch_outs = execution_function(iterator)\n",
      "  File \"/home/hodei/anaconda3/envs/molmap/lib/python3.6/site-packages/tensorflow_core/python/keras/engine/training_v2_utils.py\", line 86, in execution_function\n",
      "    distributed_function(input_fn))\n",
      "  File \"/home/hodei/anaconda3/envs/molmap/lib/python3.6/site-packages/tensorflow_core/python/eager/def_function.py\", line 457, in __call__\n",
      "    result = self._call(*args, **kwds)\n",
      "  File \"/home/hodei/anaconda3/envs/molmap/lib/python3.6/site-packages/tensorflow_core/python/eager/def_function.py\", line 526, in _call\n",
      "    return self._concrete_stateful_fn._filtered_call(canon_args, canon_kwds)  # pylint: disable=protected-access\n",
      "  File \"/home/hodei/anaconda3/envs/molmap/lib/python3.6/site-packages/tensorflow_core/python/eager/function.py\", line 1141, in _filtered_call\n",
      "    self.captured_inputs)\n",
      "  File \"/home/hodei/anaconda3/envs/molmap/lib/python3.6/site-packages/tensorflow_core/python/eager/function.py\", line 1224, in _call_flat\n",
      "    ctx, args, cancellation_manager=cancellation_manager)\n",
      "  File \"/home/hodei/anaconda3/envs/molmap/lib/python3.6/site-packages/tensorflow_core/python/eager/function.py\", line 511, in call\n",
      "    ctx=ctx)\n",
      "  File \"/home/hodei/anaconda3/envs/molmap/lib/python3.6/site-packages/tensorflow_core/python/eager/execute.py\", line 67, in quick_execute\n",
      "    six.raise_from(core._status_to_exception(e.code, message), None)\n",
      "  File \"<string>\", line 3, in raise_from\n",
      "tensorflow.python.framework.errors_impl.UnknownError:  Failed to get convolution algorithm. This is probably because cuDNN failed to initialize, so try looking to see if a warning log message was printed above.\n",
      "\t [[node model/conv2d/Conv2D (defined at /home/hodei/anaconda3/envs/molmap/lib/python3.6/site-packages/tensorflow_core/python/framework/ops.py:1751) ]] [Op:__inference_distributed_function_2875]\n",
      "\n",
      "Function call stack:\n",
      "distributed_function\n",
      "\n",
      "\n",
      "During handling of the above exception, another exception occurred:\n",
      "\n",
      "Traceback (most recent call last):\n",
      "  File \"/home/hodei/anaconda3/envs/molmap/lib/python3.6/site-packages/IPython/core/interactiveshell.py\", line 3343, in run_code\n",
      "    exec(code_obj, self.user_global_ns, self.user_ns)\n",
      "  File \"<ipython-input-7-9b2d8a865dc9>\", line 1, in <module>\n",
      "    clf.fit(trainX, trainY, validX, validY)\n",
      "  File \"/home/nuriacami/Documents/bidd-molmap/molmap/model/model.py\", line 481, in fit\n",
      "    callbacks=[performance])\n",
      "  File \"/home/hodei/anaconda3/envs/molmap/lib/python3.6/site-packages/tensorflow_core/python/keras/engine/training.py\", line 728, in fit\n",
      "    use_multiprocessing=use_multiprocessing)\n",
      "  File \"/home/hodei/anaconda3/envs/molmap/lib/python3.6/site-packages/tensorflow_core/python/keras/engine/training_v2.py\", line 372, in fit\n",
      "    prefix='val_')\n",
      "  File \"/home/hodei/anaconda3/envs/molmap/lib/python3.6/contextlib.py\", line 99, in __exit__\n",
      "    self.gen.throw(type, value, traceback)\n",
      "  File \"/home/hodei/anaconda3/envs/molmap/lib/python3.6/site-packages/tensorflow_core/python/keras/engine/training_v2.py\", line 671, in on_start\n",
      "    self.callbacks._call_end_hook(mode)\n",
      "  File \"/home/hodei/anaconda3/envs/molmap/lib/python3.6/site-packages/tensorflow_core/python/keras/callbacks.py\", line 258, in _call_end_hook\n",
      "    self.on_train_end()\n",
      "  File \"/home/hodei/anaconda3/envs/molmap/lib/python3.6/site-packages/tensorflow_core/python/keras/callbacks.py\", line 375, in on_train_end\n",
      "    callback.on_train_end(logs)\n",
      "  File \"/home/nuriacami/Documents/bidd-molmap/molmap/model/cbks2.py\", line 358, in on_train_end\n",
      "    self.model.set_weights(self.best_weights)\n",
      "  File \"/home/hodei/anaconda3/envs/molmap/lib/python3.6/site-packages/tensorflow_core/python/keras/engine/base_layer.py\", line 1322, in set_weights\n",
      "    if len(params) != len(weights):\n",
      "TypeError: object of type 'NoneType' has no len()\n",
      "\n",
      "During handling of the above exception, another exception occurred:\n",
      "\n",
      "Traceback (most recent call last):\n",
      "  File \"/home/hodei/anaconda3/envs/molmap/lib/python3.6/site-packages/IPython/core/interactiveshell.py\", line 2044, in showtraceback\n",
      "    stb = value._render_traceback_()\n",
      "AttributeError: 'TypeError' object has no attribute '_render_traceback_'\n",
      "\n",
      "During handling of the above exception, another exception occurred:\n",
      "\n",
      "Traceback (most recent call last):\n",
      "  File \"/home/hodei/anaconda3/envs/molmap/lib/python3.6/site-packages/IPython/core/interactiveshell.py\", line 3263, in run_ast_nodes\n",
      "    if (await self.run_code(code, result,  async_=asy)):\n",
      "  File \"/home/hodei/anaconda3/envs/molmap/lib/python3.6/site-packages/IPython/core/interactiveshell.py\", line 3360, in run_code\n",
      "    self.showtraceback(running_compiled_code=True)\n",
      "  File \"/home/hodei/anaconda3/envs/molmap/lib/python3.6/site-packages/IPython/core/interactiveshell.py\", line 2047, in showtraceback\n",
      "    value, tb, tb_offset=tb_offset)\n",
      "  File \"/home/hodei/anaconda3/envs/molmap/lib/python3.6/site-packages/IPython/core/ultratb.py\", line 1436, in structured_traceback\n",
      "    self, etype, value, tb, tb_offset, number_of_lines_of_context)\n",
      "  File \"/home/hodei/anaconda3/envs/molmap/lib/python3.6/site-packages/IPython/core/ultratb.py\", line 1336, in structured_traceback\n",
      "    self, etype, value, tb, tb_offset, number_of_lines_of_context\n",
      "  File \"/home/hodei/anaconda3/envs/molmap/lib/python3.6/site-packages/IPython/core/ultratb.py\", line 1193, in structured_traceback\n",
      "    tb_offset)\n",
      "  File \"/home/hodei/anaconda3/envs/molmap/lib/python3.6/site-packages/IPython/core/ultratb.py\", line 1150, in format_exception_as_a_whole\n",
      "    last_unique, recursion_repeat = find_recursion(orig_etype, evalue, records)\n",
      "  File \"/home/hodei/anaconda3/envs/molmap/lib/python3.6/site-packages/IPython/core/ultratb.py\", line 451, in find_recursion\n",
      "    return len(records), 0\n",
      "TypeError: object of type 'NoneType' has no len()\n",
      "\n",
      "During handling of the above exception, another exception occurred:\n",
      "\n",
      "Traceback (most recent call last):\n",
      "  File \"/home/hodei/anaconda3/envs/molmap/lib/python3.6/site-packages/IPython/core/interactiveshell.py\", line 2044, in showtraceback\n",
      "    stb = value._render_traceback_()\n",
      "AttributeError: 'TypeError' object has no attribute '_render_traceback_'\n",
      "\n",
      "During handling of the above exception, another exception occurred:\n",
      "\n",
      "Traceback (most recent call last):\n",
      "  File \"/home/hodei/anaconda3/envs/molmap/lib/python3.6/site-packages/IPython/core/interactiveshell.py\", line 2895, in _run_cell\n",
      "    return runner(coro)\n",
      "  File \"/home/hodei/anaconda3/envs/molmap/lib/python3.6/site-packages/IPython/core/async_helpers.py\", line 68, in _pseudo_sync_runner\n",
      "    coro.send(None)\n",
      "  File \"/home/hodei/anaconda3/envs/molmap/lib/python3.6/site-packages/IPython/core/interactiveshell.py\", line 3072, in run_cell_async\n",
      "    interactivity=interactivity, compiler=compiler, result=result)\n",
      "  File \"/home/hodei/anaconda3/envs/molmap/lib/python3.6/site-packages/IPython/core/interactiveshell.py\", line 3282, in run_ast_nodes\n",
      "    self.showtraceback()\n",
      "  File \"/home/hodei/anaconda3/envs/molmap/lib/python3.6/site-packages/IPython/core/interactiveshell.py\", line 2047, in showtraceback\n",
      "    value, tb, tb_offset=tb_offset)\n",
      "  File \"/home/hodei/anaconda3/envs/molmap/lib/python3.6/site-packages/IPython/core/ultratb.py\", line 1436, in structured_traceback\n",
      "    self, etype, value, tb, tb_offset, number_of_lines_of_context)\n",
      "  File \"/home/hodei/anaconda3/envs/molmap/lib/python3.6/site-packages/IPython/core/ultratb.py\", line 1336, in structured_traceback\n",
      "    self, etype, value, tb, tb_offset, number_of_lines_of_context\n",
      "  File \"/home/hodei/anaconda3/envs/molmap/lib/python3.6/site-packages/IPython/core/ultratb.py\", line 1211, in structured_traceback\n",
      "    chained_exceptions_tb_offset)\n",
      "  File \"/home/hodei/anaconda3/envs/molmap/lib/python3.6/site-packages/IPython/core/ultratb.py\", line 1150, in format_exception_as_a_whole\n",
      "    last_unique, recursion_repeat = find_recursion(orig_etype, evalue, records)\n",
      "  File \"/home/hodei/anaconda3/envs/molmap/lib/python3.6/site-packages/IPython/core/ultratb.py\", line 451, in find_recursion\n",
      "    return len(records), 0\n",
      "TypeError: object of type 'NoneType' has no len()\n",
      "\n",
      "During handling of the above exception, another exception occurred:\n",
      "\n",
      "Traceback (most recent call last):\n",
      "  File \"/home/hodei/anaconda3/envs/molmap/lib/python3.6/site-packages/IPython/core/interactiveshell.py\", line 2044, in showtraceback\n",
      "    stb = value._render_traceback_()\n",
      "AttributeError: 'TypeError' object has no attribute '_render_traceback_'\n",
      "\n",
      "During handling of the above exception, another exception occurred:\n",
      "\n",
      "Traceback (most recent call last):\n",
      "  File \"/home/hodei/anaconda3/envs/molmap/lib/python3.6/site-packages/IPython/core/ultratb.py\", line 1169, in get_records\n",
      "    return _fixed_getinnerframes(etb, number_of_lines_of_context, tb_offset)\n",
      "  File \"/home/hodei/anaconda3/envs/molmap/lib/python3.6/site-packages/IPython/core/ultratb.py\", line 316, in wrapped\n",
      "    return f(*args, **kwargs)\n",
      "  File \"/home/hodei/anaconda3/envs/molmap/lib/python3.6/site-packages/IPython/core/ultratb.py\", line 350, in _fixed_getinnerframes\n",
      "    records = fix_frame_records_filenames(inspect.getinnerframes(etb, context))\n",
      "  File \"/home/hodei/anaconda3/envs/molmap/lib/python3.6/inspect.py\", line 1490, in getinnerframes\n",
      "    frameinfo = (tb.tb_frame,) + getframeinfo(tb, context)\n",
      "  File \"/home/hodei/anaconda3/envs/molmap/lib/python3.6/inspect.py\", line 1448, in getframeinfo\n",
      "    filename = getsourcefile(frame) or getfile(frame)\n",
      "  File \"/home/hodei/anaconda3/envs/molmap/lib/python3.6/inspect.py\", line 696, in getsourcefile\n",
      "    if getattr(getmodule(object, filename), '__loader__', None) is not None:\n",
      "  File \"/home/hodei/anaconda3/envs/molmap/lib/python3.6/inspect.py\", line 733, in getmodule\n",
      "    if ismodule(module) and hasattr(module, '__file__'):\n",
      "  File \"/home/hodei/anaconda3/envs/molmap/lib/python3.6/site-packages/tensorflow/__init__.py\", line 50, in __getattr__\n",
      "    module = self._load()\n",
      "  File \"/home/hodei/anaconda3/envs/molmap/lib/python3.6/site-packages/tensorflow/__init__.py\", line 44, in _load\n",
      "    module = _importlib.import_module(self.__name__)\n",
      "  File \"/home/hodei/anaconda3/envs/molmap/lib/python3.6/importlib/__init__.py\", line 126, in import_module\n",
      "    return _bootstrap._gcd_import(name[level:], package, level)\n",
      "  File \"<frozen importlib._bootstrap>\", line 994, in _gcd_import\n",
      "  File \"<frozen importlib._bootstrap>\", line 971, in _find_and_load\n",
      "  File \"<frozen importlib._bootstrap>\", line 953, in _find_and_load_unlocked\n",
      "ModuleNotFoundError: No module named 'tensorflow_core.estimator'\n"
     ]
    }
   ],
   "source": [
    "clf.fit(trainX, trainY, validX, validY)"
   ]
  },
  {
   "cell_type": "markdown",
   "metadata": {},
   "source": [
    "### Plot training history"
   ]
  },
  {
   "cell_type": "code",
   "execution_count": null,
   "metadata": {},
   "outputs": [
    {
     "name": "stderr",
     "output_type": "stream",
     "text": [
      "ERROR:root:Internal Python error in the inspect module.\n",
      "Below is the traceback from this internal error.\n",
      "\n",
      "ERROR:root:Internal Python error in the inspect module.\n",
      "Below is the traceback from this internal error.\n",
      "\n",
      "ERROR:root:Internal Python error in the inspect module.\n",
      "Below is the traceback from this internal error.\n",
      "\n"
     ]
    },
    {
     "name": "stdout",
     "output_type": "stream",
     "text": [
      "Traceback (most recent call last):\n",
      "  File \"/home/hodei/anaconda3/envs/molmap/lib/python3.6/site-packages/IPython/core/interactiveshell.py\", line 3343, in run_code\n",
      "    exec(code_obj, self.user_global_ns, self.user_ns)\n",
      "  File \"<ipython-input-7-3fc3d95be89f>\", line 1, in <module>\n",
      "    pd.DataFrame(clf.history)[['auc', 'val_auc']].plot(title=\"Performance Learning Curve\")\n",
      "AttributeError: 'MultiClassEstimator' object has no attribute 'history'\n",
      "\n",
      "During handling of the above exception, another exception occurred:\n",
      "\n",
      "Traceback (most recent call last):\n",
      "  File \"/home/hodei/anaconda3/envs/molmap/lib/python3.6/site-packages/IPython/core/interactiveshell.py\", line 2044, in showtraceback\n",
      "    stb = value._render_traceback_()\n",
      "AttributeError: 'AttributeError' object has no attribute '_render_traceback_'\n",
      "\n",
      "During handling of the above exception, another exception occurred:\n",
      "\n",
      "Traceback (most recent call last):\n",
      "  File \"/home/hodei/anaconda3/envs/molmap/lib/python3.6/site-packages/IPython/core/ultratb.py\", line 1169, in get_records\n",
      "    return _fixed_getinnerframes(etb, number_of_lines_of_context, tb_offset)\n",
      "  File \"/home/hodei/anaconda3/envs/molmap/lib/python3.6/site-packages/IPython/core/ultratb.py\", line 316, in wrapped\n",
      "    return f(*args, **kwargs)\n",
      "  File \"/home/hodei/anaconda3/envs/molmap/lib/python3.6/site-packages/IPython/core/ultratb.py\", line 350, in _fixed_getinnerframes\n",
      "    records = fix_frame_records_filenames(inspect.getinnerframes(etb, context))\n",
      "  File \"/home/hodei/anaconda3/envs/molmap/lib/python3.6/inspect.py\", line 1490, in getinnerframes\n",
      "    frameinfo = (tb.tb_frame,) + getframeinfo(tb, context)\n",
      "  File \"/home/hodei/anaconda3/envs/molmap/lib/python3.6/inspect.py\", line 1448, in getframeinfo\n",
      "    filename = getsourcefile(frame) or getfile(frame)\n",
      "  File \"/home/hodei/anaconda3/envs/molmap/lib/python3.6/inspect.py\", line 696, in getsourcefile\n",
      "    if getattr(getmodule(object, filename), '__loader__', None) is not None:\n",
      "  File \"/home/hodei/anaconda3/envs/molmap/lib/python3.6/inspect.py\", line 733, in getmodule\n",
      "    if ismodule(module) and hasattr(module, '__file__'):\n",
      "  File \"/home/hodei/anaconda3/envs/molmap/lib/python3.6/site-packages/tensorflow/__init__.py\", line 50, in __getattr__\n",
      "    module = self._load()\n",
      "  File \"/home/hodei/anaconda3/envs/molmap/lib/python3.6/site-packages/tensorflow/__init__.py\", line 44, in _load\n",
      "    module = _importlib.import_module(self.__name__)\n",
      "  File \"/home/hodei/anaconda3/envs/molmap/lib/python3.6/importlib/__init__.py\", line 126, in import_module\n",
      "    return _bootstrap._gcd_import(name[level:], package, level)\n",
      "  File \"<frozen importlib._bootstrap>\", line 994, in _gcd_import\n",
      "  File \"<frozen importlib._bootstrap>\", line 971, in _find_and_load\n",
      "  File \"<frozen importlib._bootstrap>\", line 953, in _find_and_load_unlocked\n",
      "ModuleNotFoundError: No module named 'tensorflow_core.estimator'\n",
      "ERROR! Session/line number was not unique in database. History logging moved to new session 3559\n",
      "Traceback (most recent call last):\n",
      "  File \"/home/hodei/anaconda3/envs/molmap/lib/python3.6/site-packages/IPython/core/interactiveshell.py\", line 3343, in run_code\n",
      "    exec(code_obj, self.user_global_ns, self.user_ns)\n",
      "  File \"<ipython-input-7-3fc3d95be89f>\", line 1, in <module>\n",
      "    pd.DataFrame(clf.history)[['auc', 'val_auc']].plot(title=\"Performance Learning Curve\")\n",
      "AttributeError: 'MultiClassEstimator' object has no attribute 'history'\n",
      "\n",
      "During handling of the above exception, another exception occurred:\n",
      "\n",
      "Traceback (most recent call last):\n",
      "  File \"/home/hodei/anaconda3/envs/molmap/lib/python3.6/site-packages/IPython/core/interactiveshell.py\", line 2044, in showtraceback\n",
      "    stb = value._render_traceback_()\n",
      "AttributeError: 'AttributeError' object has no attribute '_render_traceback_'\n",
      "\n",
      "During handling of the above exception, another exception occurred:\n",
      "\n",
      "Traceback (most recent call last):\n",
      "  File \"/home/hodei/anaconda3/envs/molmap/lib/python3.6/site-packages/IPython/core/interactiveshell.py\", line 3263, in run_ast_nodes\n",
      "    if (await self.run_code(code, result,  async_=asy)):\n",
      "  File \"/home/hodei/anaconda3/envs/molmap/lib/python3.6/site-packages/IPython/core/interactiveshell.py\", line 3360, in run_code\n",
      "    self.showtraceback(running_compiled_code=True)\n",
      "  File \"/home/hodei/anaconda3/envs/molmap/lib/python3.6/site-packages/IPython/core/interactiveshell.py\", line 2047, in showtraceback\n",
      "    value, tb, tb_offset=tb_offset)\n",
      "  File \"/home/hodei/anaconda3/envs/molmap/lib/python3.6/site-packages/IPython/core/ultratb.py\", line 1436, in structured_traceback\n",
      "    self, etype, value, tb, tb_offset, number_of_lines_of_context)\n",
      "  File \"/home/hodei/anaconda3/envs/molmap/lib/python3.6/site-packages/IPython/core/ultratb.py\", line 1336, in structured_traceback\n",
      "    self, etype, value, tb, tb_offset, number_of_lines_of_context\n",
      "  File \"/home/hodei/anaconda3/envs/molmap/lib/python3.6/site-packages/IPython/core/ultratb.py\", line 1193, in structured_traceback\n",
      "    tb_offset)\n",
      "  File \"/home/hodei/anaconda3/envs/molmap/lib/python3.6/site-packages/IPython/core/ultratb.py\", line 1150, in format_exception_as_a_whole\n",
      "    last_unique, recursion_repeat = find_recursion(orig_etype, evalue, records)\n",
      "  File \"/home/hodei/anaconda3/envs/molmap/lib/python3.6/site-packages/IPython/core/ultratb.py\", line 451, in find_recursion\n",
      "    return len(records), 0\n",
      "TypeError: object of type 'NoneType' has no len()\n",
      "\n",
      "During handling of the above exception, another exception occurred:\n",
      "\n",
      "Traceback (most recent call last):\n",
      "  File \"/home/hodei/anaconda3/envs/molmap/lib/python3.6/site-packages/IPython/core/interactiveshell.py\", line 2044, in showtraceback\n",
      "    stb = value._render_traceback_()\n",
      "AttributeError: 'TypeError' object has no attribute '_render_traceback_'\n",
      "\n",
      "During handling of the above exception, another exception occurred:\n",
      "\n",
      "Traceback (most recent call last):\n",
      "  File \"/home/hodei/anaconda3/envs/molmap/lib/python3.6/site-packages/IPython/core/ultratb.py\", line 1169, in get_records\n",
      "    return _fixed_getinnerframes(etb, number_of_lines_of_context, tb_offset)\n",
      "  File \"/home/hodei/anaconda3/envs/molmap/lib/python3.6/site-packages/IPython/core/ultratb.py\", line 316, in wrapped\n",
      "    return f(*args, **kwargs)\n",
      "  File \"/home/hodei/anaconda3/envs/molmap/lib/python3.6/site-packages/IPython/core/ultratb.py\", line 350, in _fixed_getinnerframes\n",
      "    records = fix_frame_records_filenames(inspect.getinnerframes(etb, context))\n",
      "  File \"/home/hodei/anaconda3/envs/molmap/lib/python3.6/inspect.py\", line 1490, in getinnerframes\n",
      "    frameinfo = (tb.tb_frame,) + getframeinfo(tb, context)\n",
      "  File \"/home/hodei/anaconda3/envs/molmap/lib/python3.6/inspect.py\", line 1448, in getframeinfo\n",
      "    filename = getsourcefile(frame) or getfile(frame)\n",
      "  File \"/home/hodei/anaconda3/envs/molmap/lib/python3.6/inspect.py\", line 696, in getsourcefile\n",
      "    if getattr(getmodule(object, filename), '__loader__', None) is not None:\n",
      "  File \"/home/hodei/anaconda3/envs/molmap/lib/python3.6/inspect.py\", line 733, in getmodule\n",
      "    if ismodule(module) and hasattr(module, '__file__'):\n",
      "  File \"/home/hodei/anaconda3/envs/molmap/lib/python3.6/site-packages/tensorflow/__init__.py\", line 50, in __getattr__\n",
      "    module = self._load()\n",
      "  File \"/home/hodei/anaconda3/envs/molmap/lib/python3.6/site-packages/tensorflow/__init__.py\", line 44, in _load\n",
      "    module = _importlib.import_module(self.__name__)\n",
      "  File \"/home/hodei/anaconda3/envs/molmap/lib/python3.6/importlib/__init__.py\", line 126, in import_module\n",
      "    return _bootstrap._gcd_import(name[level:], package, level)\n",
      "  File \"<frozen importlib._bootstrap>\", line 994, in _gcd_import\n",
      "  File \"<frozen importlib._bootstrap>\", line 971, in _find_and_load\n",
      "  File \"<frozen importlib._bootstrap>\", line 953, in _find_and_load_unlocked\n",
      "ModuleNotFoundError: No module named 'tensorflow_core.estimator'\n",
      "Traceback (most recent call last):\n",
      "  File \"/home/hodei/anaconda3/envs/molmap/lib/python3.6/site-packages/IPython/core/interactiveshell.py\", line 3343, in run_code\n",
      "    exec(code_obj, self.user_global_ns, self.user_ns)\n",
      "  File \"<ipython-input-7-3fc3d95be89f>\", line 1, in <module>\n",
      "    pd.DataFrame(clf.history)[['auc', 'val_auc']].plot(title=\"Performance Learning Curve\")\n",
      "AttributeError: 'MultiClassEstimator' object has no attribute 'history'\n",
      "\n",
      "During handling of the above exception, another exception occurred:\n",
      "\n",
      "Traceback (most recent call last):\n",
      "  File \"/home/hodei/anaconda3/envs/molmap/lib/python3.6/site-packages/IPython/core/interactiveshell.py\", line 2044, in showtraceback\n",
      "    stb = value._render_traceback_()\n",
      "AttributeError: 'AttributeError' object has no attribute '_render_traceback_'\n",
      "\n",
      "During handling of the above exception, another exception occurred:\n",
      "\n",
      "Traceback (most recent call last):\n",
      "  File \"/home/hodei/anaconda3/envs/molmap/lib/python3.6/site-packages/IPython/core/interactiveshell.py\", line 3263, in run_ast_nodes\n",
      "    if (await self.run_code(code, result,  async_=asy)):\n",
      "  File \"/home/hodei/anaconda3/envs/molmap/lib/python3.6/site-packages/IPython/core/interactiveshell.py\", line 3360, in run_code\n",
      "    self.showtraceback(running_compiled_code=True)\n",
      "  File \"/home/hodei/anaconda3/envs/molmap/lib/python3.6/site-packages/IPython/core/interactiveshell.py\", line 2047, in showtraceback\n",
      "    value, tb, tb_offset=tb_offset)\n",
      "  File \"/home/hodei/anaconda3/envs/molmap/lib/python3.6/site-packages/IPython/core/ultratb.py\", line 1436, in structured_traceback\n",
      "    self, etype, value, tb, tb_offset, number_of_lines_of_context)\n",
      "  File \"/home/hodei/anaconda3/envs/molmap/lib/python3.6/site-packages/IPython/core/ultratb.py\", line 1336, in structured_traceback\n",
      "    self, etype, value, tb, tb_offset, number_of_lines_of_context\n",
      "  File \"/home/hodei/anaconda3/envs/molmap/lib/python3.6/site-packages/IPython/core/ultratb.py\", line 1193, in structured_traceback\n",
      "    tb_offset)\n",
      "  File \"/home/hodei/anaconda3/envs/molmap/lib/python3.6/site-packages/IPython/core/ultratb.py\", line 1150, in format_exception_as_a_whole\n",
      "    last_unique, recursion_repeat = find_recursion(orig_etype, evalue, records)\n",
      "  File \"/home/hodei/anaconda3/envs/molmap/lib/python3.6/site-packages/IPython/core/ultratb.py\", line 451, in find_recursion\n",
      "    return len(records), 0\n",
      "TypeError: object of type 'NoneType' has no len()\n",
      "\n",
      "During handling of the above exception, another exception occurred:\n",
      "\n",
      "Traceback (most recent call last):\n",
      "  File \"/home/hodei/anaconda3/envs/molmap/lib/python3.6/site-packages/IPython/core/interactiveshell.py\", line 2044, in showtraceback\n",
      "    stb = value._render_traceback_()\n",
      "AttributeError: 'TypeError' object has no attribute '_render_traceback_'\n",
      "\n",
      "During handling of the above exception, another exception occurred:\n",
      "\n",
      "Traceback (most recent call last):\n",
      "  File \"/home/hodei/anaconda3/envs/molmap/lib/python3.6/site-packages/IPython/core/interactiveshell.py\", line 2895, in _run_cell\n",
      "    return runner(coro)\n",
      "  File \"/home/hodei/anaconda3/envs/molmap/lib/python3.6/site-packages/IPython/core/async_helpers.py\", line 68, in _pseudo_sync_runner\n",
      "    coro.send(None)\n",
      "  File \"/home/hodei/anaconda3/envs/molmap/lib/python3.6/site-packages/IPython/core/interactiveshell.py\", line 3072, in run_cell_async\n",
      "    interactivity=interactivity, compiler=compiler, result=result)\n",
      "  File \"/home/hodei/anaconda3/envs/molmap/lib/python3.6/site-packages/IPython/core/interactiveshell.py\", line 3282, in run_ast_nodes\n",
      "    self.showtraceback()\n",
      "  File \"/home/hodei/anaconda3/envs/molmap/lib/python3.6/site-packages/IPython/core/interactiveshell.py\", line 2047, in showtraceback\n",
      "    value, tb, tb_offset=tb_offset)\n",
      "  File \"/home/hodei/anaconda3/envs/molmap/lib/python3.6/site-packages/IPython/core/ultratb.py\", line 1436, in structured_traceback\n",
      "    self, etype, value, tb, tb_offset, number_of_lines_of_context)\n",
      "  File \"/home/hodei/anaconda3/envs/molmap/lib/python3.6/site-packages/IPython/core/ultratb.py\", line 1336, in structured_traceback\n",
      "    self, etype, value, tb, tb_offset, number_of_lines_of_context\n",
      "  File \"/home/hodei/anaconda3/envs/molmap/lib/python3.6/site-packages/IPython/core/ultratb.py\", line 1211, in structured_traceback\n",
      "    chained_exceptions_tb_offset)\n",
      "  File \"/home/hodei/anaconda3/envs/molmap/lib/python3.6/site-packages/IPython/core/ultratb.py\", line 1150, in format_exception_as_a_whole\n",
      "    last_unique, recursion_repeat = find_recursion(orig_etype, evalue, records)\n",
      "  File \"/home/hodei/anaconda3/envs/molmap/lib/python3.6/site-packages/IPython/core/ultratb.py\", line 451, in find_recursion\n",
      "    return len(records), 0\n",
      "TypeError: object of type 'NoneType' has no len()\n",
      "\n",
      "During handling of the above exception, another exception occurred:\n",
      "\n",
      "Traceback (most recent call last):\n",
      "  File \"/home/hodei/anaconda3/envs/molmap/lib/python3.6/site-packages/IPython/core/interactiveshell.py\", line 2044, in showtraceback\n",
      "    stb = value._render_traceback_()\n",
      "AttributeError: 'TypeError' object has no attribute '_render_traceback_'\n",
      "\n",
      "During handling of the above exception, another exception occurred:\n",
      "\n",
      "Traceback (most recent call last):\n",
      "  File \"/home/hodei/anaconda3/envs/molmap/lib/python3.6/site-packages/IPython/core/ultratb.py\", line 1169, in get_records\n",
      "    return _fixed_getinnerframes(etb, number_of_lines_of_context, tb_offset)\n",
      "  File \"/home/hodei/anaconda3/envs/molmap/lib/python3.6/site-packages/IPython/core/ultratb.py\", line 316, in wrapped\n",
      "    return f(*args, **kwargs)\n",
      "  File \"/home/hodei/anaconda3/envs/molmap/lib/python3.6/site-packages/IPython/core/ultratb.py\", line 350, in _fixed_getinnerframes\n",
      "    records = fix_frame_records_filenames(inspect.getinnerframes(etb, context))\n",
      "  File \"/home/hodei/anaconda3/envs/molmap/lib/python3.6/inspect.py\", line 1490, in getinnerframes\n",
      "    frameinfo = (tb.tb_frame,) + getframeinfo(tb, context)\n",
      "  File \"/home/hodei/anaconda3/envs/molmap/lib/python3.6/inspect.py\", line 1448, in getframeinfo\n",
      "    filename = getsourcefile(frame) or getfile(frame)\n",
      "  File \"/home/hodei/anaconda3/envs/molmap/lib/python3.6/inspect.py\", line 696, in getsourcefile\n",
      "    if getattr(getmodule(object, filename), '__loader__', None) is not None:\n",
      "  File \"/home/hodei/anaconda3/envs/molmap/lib/python3.6/inspect.py\", line 733, in getmodule\n",
      "    if ismodule(module) and hasattr(module, '__file__'):\n",
      "  File \"/home/hodei/anaconda3/envs/molmap/lib/python3.6/site-packages/tensorflow/__init__.py\", line 50, in __getattr__\n",
      "    module = self._load()\n",
      "  File \"/home/hodei/anaconda3/envs/molmap/lib/python3.6/site-packages/tensorflow/__init__.py\", line 44, in _load\n",
      "    module = _importlib.import_module(self.__name__)\n",
      "  File \"/home/hodei/anaconda3/envs/molmap/lib/python3.6/importlib/__init__.py\", line 126, in import_module\n",
      "    return _bootstrap._gcd_import(name[level:], package, level)\n",
      "  File \"<frozen importlib._bootstrap>\", line 994, in _gcd_import\n",
      "  File \"<frozen importlib._bootstrap>\", line 971, in _find_and_load\n",
      "  File \"<frozen importlib._bootstrap>\", line 953, in _find_and_load_unlocked\n",
      "ModuleNotFoundError: No module named 'tensorflow_core.estimator'\n"
     ]
    }
   ],
   "source": [
    "pd.DataFrame(clf.history)[['auc', 'val_auc']].plot(title=\"Performance Learning Curve\")"
   ]
  },
  {
   "cell_type": "code",
   "execution_count": null,
   "metadata": {},
   "outputs": [
    {
     "name": "stderr",
     "output_type": "stream",
     "text": [
      "ERROR:root:Internal Python error in the inspect module.\n",
      "Below is the traceback from this internal error.\n",
      "\n",
      "ERROR:root:Internal Python error in the inspect module.\n",
      "Below is the traceback from this internal error.\n",
      "\n",
      "ERROR:root:Internal Python error in the inspect module.\n",
      "Below is the traceback from this internal error.\n",
      "\n"
     ]
    },
    {
     "name": "stdout",
     "output_type": "stream",
     "text": [
      "Traceback (most recent call last):\n",
      "  File \"/home/hodei/anaconda3/envs/molmap/lib/python3.6/site-packages/IPython/core/interactiveshell.py\", line 3343, in run_code\n",
      "    exec(code_obj, self.user_global_ns, self.user_ns)\n",
      "  File \"<ipython-input-7-79630c28df07>\", line 1, in <module>\n",
      "    pd.DataFrame(clf.history)[['loss', 'val_loss']].plot(title=\"Optimization Learning Curve\")\n",
      "AttributeError: 'MultiClassEstimator' object has no attribute 'history'\n",
      "\n",
      "During handling of the above exception, another exception occurred:\n",
      "\n",
      "Traceback (most recent call last):\n",
      "  File \"/home/hodei/anaconda3/envs/molmap/lib/python3.6/site-packages/IPython/core/interactiveshell.py\", line 2044, in showtraceback\n",
      "    stb = value._render_traceback_()\n",
      "AttributeError: 'AttributeError' object has no attribute '_render_traceback_'\n",
      "\n",
      "During handling of the above exception, another exception occurred:\n",
      "\n",
      "Traceback (most recent call last):\n",
      "  File \"/home/hodei/anaconda3/envs/molmap/lib/python3.6/site-packages/IPython/core/ultratb.py\", line 1169, in get_records\n",
      "    return _fixed_getinnerframes(etb, number_of_lines_of_context, tb_offset)\n",
      "  File \"/home/hodei/anaconda3/envs/molmap/lib/python3.6/site-packages/IPython/core/ultratb.py\", line 316, in wrapped\n",
      "    return f(*args, **kwargs)\n",
      "  File \"/home/hodei/anaconda3/envs/molmap/lib/python3.6/site-packages/IPython/core/ultratb.py\", line 350, in _fixed_getinnerframes\n",
      "    records = fix_frame_records_filenames(inspect.getinnerframes(etb, context))\n",
      "  File \"/home/hodei/anaconda3/envs/molmap/lib/python3.6/inspect.py\", line 1490, in getinnerframes\n",
      "    frameinfo = (tb.tb_frame,) + getframeinfo(tb, context)\n",
      "  File \"/home/hodei/anaconda3/envs/molmap/lib/python3.6/inspect.py\", line 1448, in getframeinfo\n",
      "    filename = getsourcefile(frame) or getfile(frame)\n",
      "  File \"/home/hodei/anaconda3/envs/molmap/lib/python3.6/inspect.py\", line 696, in getsourcefile\n",
      "    if getattr(getmodule(object, filename), '__loader__', None) is not None:\n",
      "  File \"/home/hodei/anaconda3/envs/molmap/lib/python3.6/inspect.py\", line 733, in getmodule\n",
      "    if ismodule(module) and hasattr(module, '__file__'):\n",
      "  File \"/home/hodei/anaconda3/envs/molmap/lib/python3.6/site-packages/tensorflow/__init__.py\", line 50, in __getattr__\n",
      "    module = self._load()\n",
      "  File \"/home/hodei/anaconda3/envs/molmap/lib/python3.6/site-packages/tensorflow/__init__.py\", line 44, in _load\n",
      "    module = _importlib.import_module(self.__name__)\n",
      "  File \"/home/hodei/anaconda3/envs/molmap/lib/python3.6/importlib/__init__.py\", line 126, in import_module\n",
      "    return _bootstrap._gcd_import(name[level:], package, level)\n",
      "  File \"<frozen importlib._bootstrap>\", line 994, in _gcd_import\n",
      "  File \"<frozen importlib._bootstrap>\", line 971, in _find_and_load\n",
      "  File \"<frozen importlib._bootstrap>\", line 953, in _find_and_load_unlocked\n",
      "ModuleNotFoundError: No module named 'tensorflow_core.estimator'\n",
      "ERROR! Session/line number was not unique in database. History logging moved to new session 3560\n",
      "Traceback (most recent call last):\n",
      "  File \"/home/hodei/anaconda3/envs/molmap/lib/python3.6/site-packages/IPython/core/interactiveshell.py\", line 3343, in run_code\n",
      "    exec(code_obj, self.user_global_ns, self.user_ns)\n",
      "  File \"<ipython-input-7-79630c28df07>\", line 1, in <module>\n",
      "    pd.DataFrame(clf.history)[['loss', 'val_loss']].plot(title=\"Optimization Learning Curve\")\n",
      "AttributeError: 'MultiClassEstimator' object has no attribute 'history'\n",
      "\n",
      "During handling of the above exception, another exception occurred:\n",
      "\n",
      "Traceback (most recent call last):\n",
      "  File \"/home/hodei/anaconda3/envs/molmap/lib/python3.6/site-packages/IPython/core/interactiveshell.py\", line 2044, in showtraceback\n",
      "    stb = value._render_traceback_()\n",
      "AttributeError: 'AttributeError' object has no attribute '_render_traceback_'\n",
      "\n",
      "During handling of the above exception, another exception occurred:\n",
      "\n",
      "Traceback (most recent call last):\n",
      "  File \"/home/hodei/anaconda3/envs/molmap/lib/python3.6/site-packages/IPython/core/interactiveshell.py\", line 3263, in run_ast_nodes\n",
      "    if (await self.run_code(code, result,  async_=asy)):\n",
      "  File \"/home/hodei/anaconda3/envs/molmap/lib/python3.6/site-packages/IPython/core/interactiveshell.py\", line 3360, in run_code\n",
      "    self.showtraceback(running_compiled_code=True)\n",
      "  File \"/home/hodei/anaconda3/envs/molmap/lib/python3.6/site-packages/IPython/core/interactiveshell.py\", line 2047, in showtraceback\n",
      "    value, tb, tb_offset=tb_offset)\n",
      "  File \"/home/hodei/anaconda3/envs/molmap/lib/python3.6/site-packages/IPython/core/ultratb.py\", line 1436, in structured_traceback\n",
      "    self, etype, value, tb, tb_offset, number_of_lines_of_context)\n",
      "  File \"/home/hodei/anaconda3/envs/molmap/lib/python3.6/site-packages/IPython/core/ultratb.py\", line 1336, in structured_traceback\n",
      "    self, etype, value, tb, tb_offset, number_of_lines_of_context\n",
      "  File \"/home/hodei/anaconda3/envs/molmap/lib/python3.6/site-packages/IPython/core/ultratb.py\", line 1193, in structured_traceback\n",
      "    tb_offset)\n",
      "  File \"/home/hodei/anaconda3/envs/molmap/lib/python3.6/site-packages/IPython/core/ultratb.py\", line 1150, in format_exception_as_a_whole\n",
      "    last_unique, recursion_repeat = find_recursion(orig_etype, evalue, records)\n",
      "  File \"/home/hodei/anaconda3/envs/molmap/lib/python3.6/site-packages/IPython/core/ultratb.py\", line 451, in find_recursion\n",
      "    return len(records), 0\n",
      "TypeError: object of type 'NoneType' has no len()\n",
      "\n",
      "During handling of the above exception, another exception occurred:\n",
      "\n",
      "Traceback (most recent call last):\n",
      "  File \"/home/hodei/anaconda3/envs/molmap/lib/python3.6/site-packages/IPython/core/interactiveshell.py\", line 2044, in showtraceback\n",
      "    stb = value._render_traceback_()\n",
      "AttributeError: 'TypeError' object has no attribute '_render_traceback_'\n",
      "\n",
      "During handling of the above exception, another exception occurred:\n",
      "\n",
      "Traceback (most recent call last):\n",
      "  File \"/home/hodei/anaconda3/envs/molmap/lib/python3.6/site-packages/IPython/core/ultratb.py\", line 1169, in get_records\n",
      "    return _fixed_getinnerframes(etb, number_of_lines_of_context, tb_offset)\n",
      "  File \"/home/hodei/anaconda3/envs/molmap/lib/python3.6/site-packages/IPython/core/ultratb.py\", line 316, in wrapped\n",
      "    return f(*args, **kwargs)\n",
      "  File \"/home/hodei/anaconda3/envs/molmap/lib/python3.6/site-packages/IPython/core/ultratb.py\", line 350, in _fixed_getinnerframes\n",
      "    records = fix_frame_records_filenames(inspect.getinnerframes(etb, context))\n",
      "  File \"/home/hodei/anaconda3/envs/molmap/lib/python3.6/inspect.py\", line 1490, in getinnerframes\n",
      "    frameinfo = (tb.tb_frame,) + getframeinfo(tb, context)\n",
      "  File \"/home/hodei/anaconda3/envs/molmap/lib/python3.6/inspect.py\", line 1448, in getframeinfo\n",
      "    filename = getsourcefile(frame) or getfile(frame)\n",
      "  File \"/home/hodei/anaconda3/envs/molmap/lib/python3.6/inspect.py\", line 696, in getsourcefile\n",
      "    if getattr(getmodule(object, filename), '__loader__', None) is not None:\n",
      "  File \"/home/hodei/anaconda3/envs/molmap/lib/python3.6/inspect.py\", line 733, in getmodule\n",
      "    if ismodule(module) and hasattr(module, '__file__'):\n",
      "  File \"/home/hodei/anaconda3/envs/molmap/lib/python3.6/site-packages/tensorflow/__init__.py\", line 50, in __getattr__\n",
      "    module = self._load()\n",
      "  File \"/home/hodei/anaconda3/envs/molmap/lib/python3.6/site-packages/tensorflow/__init__.py\", line 44, in _load\n",
      "    module = _importlib.import_module(self.__name__)\n",
      "  File \"/home/hodei/anaconda3/envs/molmap/lib/python3.6/importlib/__init__.py\", line 126, in import_module\n",
      "    return _bootstrap._gcd_import(name[level:], package, level)\n",
      "  File \"<frozen importlib._bootstrap>\", line 994, in _gcd_import\n",
      "  File \"<frozen importlib._bootstrap>\", line 971, in _find_and_load\n",
      "  File \"<frozen importlib._bootstrap>\", line 953, in _find_and_load_unlocked\n",
      "ModuleNotFoundError: No module named 'tensorflow_core.estimator'\n",
      "Traceback (most recent call last):\n",
      "  File \"/home/hodei/anaconda3/envs/molmap/lib/python3.6/site-packages/IPython/core/interactiveshell.py\", line 3343, in run_code\n",
      "    exec(code_obj, self.user_global_ns, self.user_ns)\n",
      "  File \"<ipython-input-7-79630c28df07>\", line 1, in <module>\n",
      "    pd.DataFrame(clf.history)[['loss', 'val_loss']].plot(title=\"Optimization Learning Curve\")\n",
      "AttributeError: 'MultiClassEstimator' object has no attribute 'history'\n",
      "\n",
      "During handling of the above exception, another exception occurred:\n",
      "\n",
      "Traceback (most recent call last):\n",
      "  File \"/home/hodei/anaconda3/envs/molmap/lib/python3.6/site-packages/IPython/core/interactiveshell.py\", line 2044, in showtraceback\n",
      "    stb = value._render_traceback_()\n",
      "AttributeError: 'AttributeError' object has no attribute '_render_traceback_'\n",
      "\n",
      "During handling of the above exception, another exception occurred:\n",
      "\n",
      "Traceback (most recent call last):\n",
      "  File \"/home/hodei/anaconda3/envs/molmap/lib/python3.6/site-packages/IPython/core/interactiveshell.py\", line 3263, in run_ast_nodes\n",
      "    if (await self.run_code(code, result,  async_=asy)):\n",
      "  File \"/home/hodei/anaconda3/envs/molmap/lib/python3.6/site-packages/IPython/core/interactiveshell.py\", line 3360, in run_code\n",
      "    self.showtraceback(running_compiled_code=True)\n",
      "  File \"/home/hodei/anaconda3/envs/molmap/lib/python3.6/site-packages/IPython/core/interactiveshell.py\", line 2047, in showtraceback\n",
      "    value, tb, tb_offset=tb_offset)\n",
      "  File \"/home/hodei/anaconda3/envs/molmap/lib/python3.6/site-packages/IPython/core/ultratb.py\", line 1436, in structured_traceback\n",
      "    self, etype, value, tb, tb_offset, number_of_lines_of_context)\n",
      "  File \"/home/hodei/anaconda3/envs/molmap/lib/python3.6/site-packages/IPython/core/ultratb.py\", line 1336, in structured_traceback\n",
      "    self, etype, value, tb, tb_offset, number_of_lines_of_context\n",
      "  File \"/home/hodei/anaconda3/envs/molmap/lib/python3.6/site-packages/IPython/core/ultratb.py\", line 1193, in structured_traceback\n",
      "    tb_offset)\n",
      "  File \"/home/hodei/anaconda3/envs/molmap/lib/python3.6/site-packages/IPython/core/ultratb.py\", line 1150, in format_exception_as_a_whole\n",
      "    last_unique, recursion_repeat = find_recursion(orig_etype, evalue, records)\n",
      "  File \"/home/hodei/anaconda3/envs/molmap/lib/python3.6/site-packages/IPython/core/ultratb.py\", line 451, in find_recursion\n",
      "    return len(records), 0\n",
      "TypeError: object of type 'NoneType' has no len()\n",
      "\n",
      "During handling of the above exception, another exception occurred:\n",
      "\n",
      "Traceback (most recent call last):\n",
      "  File \"/home/hodei/anaconda3/envs/molmap/lib/python3.6/site-packages/IPython/core/interactiveshell.py\", line 2044, in showtraceback\n",
      "    stb = value._render_traceback_()\n",
      "AttributeError: 'TypeError' object has no attribute '_render_traceback_'\n",
      "\n",
      "During handling of the above exception, another exception occurred:\n",
      "\n",
      "Traceback (most recent call last):\n",
      "  File \"/home/hodei/anaconda3/envs/molmap/lib/python3.6/site-packages/IPython/core/interactiveshell.py\", line 2895, in _run_cell\n",
      "    return runner(coro)\n",
      "  File \"/home/hodei/anaconda3/envs/molmap/lib/python3.6/site-packages/IPython/core/async_helpers.py\", line 68, in _pseudo_sync_runner\n",
      "    coro.send(None)\n",
      "  File \"/home/hodei/anaconda3/envs/molmap/lib/python3.6/site-packages/IPython/core/interactiveshell.py\", line 3072, in run_cell_async\n",
      "    interactivity=interactivity, compiler=compiler, result=result)\n",
      "  File \"/home/hodei/anaconda3/envs/molmap/lib/python3.6/site-packages/IPython/core/interactiveshell.py\", line 3282, in run_ast_nodes\n",
      "    self.showtraceback()\n",
      "  File \"/home/hodei/anaconda3/envs/molmap/lib/python3.6/site-packages/IPython/core/interactiveshell.py\", line 2047, in showtraceback\n",
      "    value, tb, tb_offset=tb_offset)\n",
      "  File \"/home/hodei/anaconda3/envs/molmap/lib/python3.6/site-packages/IPython/core/ultratb.py\", line 1436, in structured_traceback\n",
      "    self, etype, value, tb, tb_offset, number_of_lines_of_context)\n",
      "  File \"/home/hodei/anaconda3/envs/molmap/lib/python3.6/site-packages/IPython/core/ultratb.py\", line 1336, in structured_traceback\n",
      "    self, etype, value, tb, tb_offset, number_of_lines_of_context\n",
      "  File \"/home/hodei/anaconda3/envs/molmap/lib/python3.6/site-packages/IPython/core/ultratb.py\", line 1211, in structured_traceback\n",
      "    chained_exceptions_tb_offset)\n",
      "  File \"/home/hodei/anaconda3/envs/molmap/lib/python3.6/site-packages/IPython/core/ultratb.py\", line 1150, in format_exception_as_a_whole\n",
      "    last_unique, recursion_repeat = find_recursion(orig_etype, evalue, records)\n",
      "  File \"/home/hodei/anaconda3/envs/molmap/lib/python3.6/site-packages/IPython/core/ultratb.py\", line 451, in find_recursion\n",
      "    return len(records), 0\n",
      "TypeError: object of type 'NoneType' has no len()\n",
      "\n",
      "During handling of the above exception, another exception occurred:\n",
      "\n",
      "Traceback (most recent call last):\n",
      "  File \"/home/hodei/anaconda3/envs/molmap/lib/python3.6/site-packages/IPython/core/interactiveshell.py\", line 2044, in showtraceback\n",
      "    stb = value._render_traceback_()\n",
      "AttributeError: 'TypeError' object has no attribute '_render_traceback_'\n",
      "\n",
      "During handling of the above exception, another exception occurred:\n",
      "\n",
      "Traceback (most recent call last):\n",
      "  File \"/home/hodei/anaconda3/envs/molmap/lib/python3.6/site-packages/IPython/core/ultratb.py\", line 1169, in get_records\n",
      "    return _fixed_getinnerframes(etb, number_of_lines_of_context, tb_offset)\n",
      "  File \"/home/hodei/anaconda3/envs/molmap/lib/python3.6/site-packages/IPython/core/ultratb.py\", line 316, in wrapped\n",
      "    return f(*args, **kwargs)\n",
      "  File \"/home/hodei/anaconda3/envs/molmap/lib/python3.6/site-packages/IPython/core/ultratb.py\", line 350, in _fixed_getinnerframes\n",
      "    records = fix_frame_records_filenames(inspect.getinnerframes(etb, context))\n",
      "  File \"/home/hodei/anaconda3/envs/molmap/lib/python3.6/inspect.py\", line 1490, in getinnerframes\n",
      "    frameinfo = (tb.tb_frame,) + getframeinfo(tb, context)\n",
      "  File \"/home/hodei/anaconda3/envs/molmap/lib/python3.6/inspect.py\", line 1448, in getframeinfo\n",
      "    filename = getsourcefile(frame) or getfile(frame)\n",
      "  File \"/home/hodei/anaconda3/envs/molmap/lib/python3.6/inspect.py\", line 696, in getsourcefile\n",
      "    if getattr(getmodule(object, filename), '__loader__', None) is not None:\n",
      "  File \"/home/hodei/anaconda3/envs/molmap/lib/python3.6/inspect.py\", line 733, in getmodule\n",
      "    if ismodule(module) and hasattr(module, '__file__'):\n",
      "  File \"/home/hodei/anaconda3/envs/molmap/lib/python3.6/site-packages/tensorflow/__init__.py\", line 50, in __getattr__\n",
      "    module = self._load()\n",
      "  File \"/home/hodei/anaconda3/envs/molmap/lib/python3.6/site-packages/tensorflow/__init__.py\", line 44, in _load\n",
      "    module = _importlib.import_module(self.__name__)\n",
      "  File \"/home/hodei/anaconda3/envs/molmap/lib/python3.6/importlib/__init__.py\", line 126, in import_module\n",
      "    return _bootstrap._gcd_import(name[level:], package, level)\n",
      "  File \"<frozen importlib._bootstrap>\", line 994, in _gcd_import\n",
      "  File \"<frozen importlib._bootstrap>\", line 971, in _find_and_load\n",
      "  File \"<frozen importlib._bootstrap>\", line 953, in _find_and_load_unlocked\n",
      "ModuleNotFoundError: No module named 'tensorflow_core.estimator'\n"
     ]
    }
   ],
   "source": [
    "pd.DataFrame(clf.history)[['loss', 'val_loss']].plot(title=\"Optimization Learning Curve\")"
   ]
  },
  {
   "cell_type": "code",
   "execution_count": null,
   "metadata": {},
   "outputs": [
    {
     "name": "stderr",
     "output_type": "stream",
     "text": [
      "ERROR:root:Internal Python error in the inspect module.\n",
      "Below is the traceback from this internal error.\n",
      "\n",
      "ERROR:root:Internal Python error in the inspect module.\n",
      "Below is the traceback from this internal error.\n",
      "\n",
      "ERROR:root:Internal Python error in the inspect module.\n",
      "Below is the traceback from this internal error.\n",
      "\n"
     ]
    },
    {
     "name": "stdout",
     "output_type": "stream",
     "text": [
      "Traceback (most recent call last):\n",
      "  File \"/home/hodei/anaconda3/envs/molmap/lib/python3.6/site-packages/IPython/core/interactiveshell.py\", line 3343, in run_code\n",
      "    exec(code_obj, self.user_global_ns, self.user_ns)\n",
      "  File \"<ipython-input-7-e2e31f9dd91e>\", line 1, in <module>\n",
      "    print('Best epochs: %.2f, Best loss: %.2f' % (clf._performance.best_epoch, clf._performance.best))\n",
      "AttributeError: 'MultiClassEstimator' object has no attribute '_performance'\n",
      "\n",
      "During handling of the above exception, another exception occurred:\n",
      "\n",
      "Traceback (most recent call last):\n",
      "  File \"/home/hodei/anaconda3/envs/molmap/lib/python3.6/site-packages/IPython/core/interactiveshell.py\", line 2044, in showtraceback\n",
      "    stb = value._render_traceback_()\n",
      "AttributeError: 'AttributeError' object has no attribute '_render_traceback_'\n",
      "\n",
      "During handling of the above exception, another exception occurred:\n",
      "\n",
      "Traceback (most recent call last):\n",
      "  File \"/home/hodei/anaconda3/envs/molmap/lib/python3.6/site-packages/IPython/core/ultratb.py\", line 1169, in get_records\n",
      "    return _fixed_getinnerframes(etb, number_of_lines_of_context, tb_offset)\n",
      "  File \"/home/hodei/anaconda3/envs/molmap/lib/python3.6/site-packages/IPython/core/ultratb.py\", line 316, in wrapped\n",
      "    return f(*args, **kwargs)\n",
      "  File \"/home/hodei/anaconda3/envs/molmap/lib/python3.6/site-packages/IPython/core/ultratb.py\", line 350, in _fixed_getinnerframes\n",
      "    records = fix_frame_records_filenames(inspect.getinnerframes(etb, context))\n",
      "  File \"/home/hodei/anaconda3/envs/molmap/lib/python3.6/inspect.py\", line 1490, in getinnerframes\n",
      "    frameinfo = (tb.tb_frame,) + getframeinfo(tb, context)\n",
      "  File \"/home/hodei/anaconda3/envs/molmap/lib/python3.6/inspect.py\", line 1448, in getframeinfo\n",
      "    filename = getsourcefile(frame) or getfile(frame)\n",
      "  File \"/home/hodei/anaconda3/envs/molmap/lib/python3.6/inspect.py\", line 696, in getsourcefile\n",
      "    if getattr(getmodule(object, filename), '__loader__', None) is not None:\n",
      "  File \"/home/hodei/anaconda3/envs/molmap/lib/python3.6/inspect.py\", line 733, in getmodule\n",
      "    if ismodule(module) and hasattr(module, '__file__'):\n",
      "  File \"/home/hodei/anaconda3/envs/molmap/lib/python3.6/site-packages/tensorflow/__init__.py\", line 50, in __getattr__\n",
      "    module = self._load()\n",
      "  File \"/home/hodei/anaconda3/envs/molmap/lib/python3.6/site-packages/tensorflow/__init__.py\", line 44, in _load\n",
      "    module = _importlib.import_module(self.__name__)\n",
      "  File \"/home/hodei/anaconda3/envs/molmap/lib/python3.6/importlib/__init__.py\", line 126, in import_module\n",
      "    return _bootstrap._gcd_import(name[level:], package, level)\n",
      "  File \"<frozen importlib._bootstrap>\", line 994, in _gcd_import\n",
      "  File \"<frozen importlib._bootstrap>\", line 971, in _find_and_load\n",
      "  File \"<frozen importlib._bootstrap>\", line 953, in _find_and_load_unlocked\n",
      "ModuleNotFoundError: No module named 'tensorflow_core.estimator'\n",
      "ERROR! Session/line number was not unique in database. History logging moved to new session 3561\n",
      "Traceback (most recent call last):\n",
      "  File \"/home/hodei/anaconda3/envs/molmap/lib/python3.6/site-packages/IPython/core/interactiveshell.py\", line 3343, in run_code\n",
      "    exec(code_obj, self.user_global_ns, self.user_ns)\n",
      "  File \"<ipython-input-7-e2e31f9dd91e>\", line 1, in <module>\n",
      "    print('Best epochs: %.2f, Best loss: %.2f' % (clf._performance.best_epoch, clf._performance.best))\n",
      "AttributeError: 'MultiClassEstimator' object has no attribute '_performance'\n",
      "\n",
      "During handling of the above exception, another exception occurred:\n",
      "\n",
      "Traceback (most recent call last):\n",
      "  File \"/home/hodei/anaconda3/envs/molmap/lib/python3.6/site-packages/IPython/core/interactiveshell.py\", line 2044, in showtraceback\n",
      "    stb = value._render_traceback_()\n",
      "AttributeError: 'AttributeError' object has no attribute '_render_traceback_'\n",
      "\n",
      "During handling of the above exception, another exception occurred:\n",
      "\n",
      "Traceback (most recent call last):\n",
      "  File \"/home/hodei/anaconda3/envs/molmap/lib/python3.6/site-packages/IPython/core/interactiveshell.py\", line 3263, in run_ast_nodes\n",
      "    if (await self.run_code(code, result,  async_=asy)):\n",
      "  File \"/home/hodei/anaconda3/envs/molmap/lib/python3.6/site-packages/IPython/core/interactiveshell.py\", line 3360, in run_code\n",
      "    self.showtraceback(running_compiled_code=True)\n",
      "  File \"/home/hodei/anaconda3/envs/molmap/lib/python3.6/site-packages/IPython/core/interactiveshell.py\", line 2047, in showtraceback\n",
      "    value, tb, tb_offset=tb_offset)\n",
      "  File \"/home/hodei/anaconda3/envs/molmap/lib/python3.6/site-packages/IPython/core/ultratb.py\", line 1436, in structured_traceback\n",
      "    self, etype, value, tb, tb_offset, number_of_lines_of_context)\n",
      "  File \"/home/hodei/anaconda3/envs/molmap/lib/python3.6/site-packages/IPython/core/ultratb.py\", line 1336, in structured_traceback\n",
      "    self, etype, value, tb, tb_offset, number_of_lines_of_context\n",
      "  File \"/home/hodei/anaconda3/envs/molmap/lib/python3.6/site-packages/IPython/core/ultratb.py\", line 1193, in structured_traceback\n",
      "    tb_offset)\n",
      "  File \"/home/hodei/anaconda3/envs/molmap/lib/python3.6/site-packages/IPython/core/ultratb.py\", line 1150, in format_exception_as_a_whole\n",
      "    last_unique, recursion_repeat = find_recursion(orig_etype, evalue, records)\n",
      "  File \"/home/hodei/anaconda3/envs/molmap/lib/python3.6/site-packages/IPython/core/ultratb.py\", line 451, in find_recursion\n",
      "    return len(records), 0\n",
      "TypeError: object of type 'NoneType' has no len()\n",
      "\n",
      "During handling of the above exception, another exception occurred:\n",
      "\n",
      "Traceback (most recent call last):\n",
      "  File \"/home/hodei/anaconda3/envs/molmap/lib/python3.6/site-packages/IPython/core/interactiveshell.py\", line 2044, in showtraceback\n",
      "    stb = value._render_traceback_()\n",
      "AttributeError: 'TypeError' object has no attribute '_render_traceback_'\n",
      "\n",
      "During handling of the above exception, another exception occurred:\n",
      "\n",
      "Traceback (most recent call last):\n",
      "  File \"/home/hodei/anaconda3/envs/molmap/lib/python3.6/site-packages/IPython/core/ultratb.py\", line 1169, in get_records\n",
      "    return _fixed_getinnerframes(etb, number_of_lines_of_context, tb_offset)\n",
      "  File \"/home/hodei/anaconda3/envs/molmap/lib/python3.6/site-packages/IPython/core/ultratb.py\", line 316, in wrapped\n",
      "    return f(*args, **kwargs)\n",
      "  File \"/home/hodei/anaconda3/envs/molmap/lib/python3.6/site-packages/IPython/core/ultratb.py\", line 350, in _fixed_getinnerframes\n",
      "    records = fix_frame_records_filenames(inspect.getinnerframes(etb, context))\n",
      "  File \"/home/hodei/anaconda3/envs/molmap/lib/python3.6/inspect.py\", line 1490, in getinnerframes\n",
      "    frameinfo = (tb.tb_frame,) + getframeinfo(tb, context)\n",
      "  File \"/home/hodei/anaconda3/envs/molmap/lib/python3.6/inspect.py\", line 1448, in getframeinfo\n",
      "    filename = getsourcefile(frame) or getfile(frame)\n",
      "  File \"/home/hodei/anaconda3/envs/molmap/lib/python3.6/inspect.py\", line 696, in getsourcefile\n",
      "    if getattr(getmodule(object, filename), '__loader__', None) is not None:\n",
      "  File \"/home/hodei/anaconda3/envs/molmap/lib/python3.6/inspect.py\", line 733, in getmodule\n",
      "    if ismodule(module) and hasattr(module, '__file__'):\n",
      "  File \"/home/hodei/anaconda3/envs/molmap/lib/python3.6/site-packages/tensorflow/__init__.py\", line 50, in __getattr__\n",
      "    module = self._load()\n",
      "  File \"/home/hodei/anaconda3/envs/molmap/lib/python3.6/site-packages/tensorflow/__init__.py\", line 44, in _load\n",
      "    module = _importlib.import_module(self.__name__)\n",
      "  File \"/home/hodei/anaconda3/envs/molmap/lib/python3.6/importlib/__init__.py\", line 126, in import_module\n",
      "    return _bootstrap._gcd_import(name[level:], package, level)\n",
      "  File \"<frozen importlib._bootstrap>\", line 994, in _gcd_import\n",
      "  File \"<frozen importlib._bootstrap>\", line 971, in _find_and_load\n",
      "  File \"<frozen importlib._bootstrap>\", line 953, in _find_and_load_unlocked\n",
      "ModuleNotFoundError: No module named 'tensorflow_core.estimator'\n",
      "Traceback (most recent call last):\n",
      "  File \"/home/hodei/anaconda3/envs/molmap/lib/python3.6/site-packages/IPython/core/interactiveshell.py\", line 3343, in run_code\n",
      "    exec(code_obj, self.user_global_ns, self.user_ns)\n",
      "  File \"<ipython-input-7-e2e31f9dd91e>\", line 1, in <module>\n",
      "    print('Best epochs: %.2f, Best loss: %.2f' % (clf._performance.best_epoch, clf._performance.best))\n",
      "AttributeError: 'MultiClassEstimator' object has no attribute '_performance'\n",
      "\n",
      "During handling of the above exception, another exception occurred:\n",
      "\n",
      "Traceback (most recent call last):\n",
      "  File \"/home/hodei/anaconda3/envs/molmap/lib/python3.6/site-packages/IPython/core/interactiveshell.py\", line 2044, in showtraceback\n",
      "    stb = value._render_traceback_()\n",
      "AttributeError: 'AttributeError' object has no attribute '_render_traceback_'\n",
      "\n",
      "During handling of the above exception, another exception occurred:\n",
      "\n",
      "Traceback (most recent call last):\n",
      "  File \"/home/hodei/anaconda3/envs/molmap/lib/python3.6/site-packages/IPython/core/interactiveshell.py\", line 3263, in run_ast_nodes\n",
      "    if (await self.run_code(code, result,  async_=asy)):\n",
      "  File \"/home/hodei/anaconda3/envs/molmap/lib/python3.6/site-packages/IPython/core/interactiveshell.py\", line 3360, in run_code\n",
      "    self.showtraceback(running_compiled_code=True)\n",
      "  File \"/home/hodei/anaconda3/envs/molmap/lib/python3.6/site-packages/IPython/core/interactiveshell.py\", line 2047, in showtraceback\n",
      "    value, tb, tb_offset=tb_offset)\n",
      "  File \"/home/hodei/anaconda3/envs/molmap/lib/python3.6/site-packages/IPython/core/ultratb.py\", line 1436, in structured_traceback\n",
      "    self, etype, value, tb, tb_offset, number_of_lines_of_context)\n",
      "  File \"/home/hodei/anaconda3/envs/molmap/lib/python3.6/site-packages/IPython/core/ultratb.py\", line 1336, in structured_traceback\n",
      "    self, etype, value, tb, tb_offset, number_of_lines_of_context\n",
      "  File \"/home/hodei/anaconda3/envs/molmap/lib/python3.6/site-packages/IPython/core/ultratb.py\", line 1193, in structured_traceback\n",
      "    tb_offset)\n",
      "  File \"/home/hodei/anaconda3/envs/molmap/lib/python3.6/site-packages/IPython/core/ultratb.py\", line 1150, in format_exception_as_a_whole\n",
      "    last_unique, recursion_repeat = find_recursion(orig_etype, evalue, records)\n",
      "  File \"/home/hodei/anaconda3/envs/molmap/lib/python3.6/site-packages/IPython/core/ultratb.py\", line 451, in find_recursion\n",
      "    return len(records), 0\n",
      "TypeError: object of type 'NoneType' has no len()\n",
      "\n",
      "During handling of the above exception, another exception occurred:\n",
      "\n",
      "Traceback (most recent call last):\n",
      "  File \"/home/hodei/anaconda3/envs/molmap/lib/python3.6/site-packages/IPython/core/interactiveshell.py\", line 2044, in showtraceback\n",
      "    stb = value._render_traceback_()\n",
      "AttributeError: 'TypeError' object has no attribute '_render_traceback_'\n",
      "\n",
      "During handling of the above exception, another exception occurred:\n",
      "\n",
      "Traceback (most recent call last):\n",
      "  File \"/home/hodei/anaconda3/envs/molmap/lib/python3.6/site-packages/IPython/core/interactiveshell.py\", line 2895, in _run_cell\n",
      "    return runner(coro)\n",
      "  File \"/home/hodei/anaconda3/envs/molmap/lib/python3.6/site-packages/IPython/core/async_helpers.py\", line 68, in _pseudo_sync_runner\n",
      "    coro.send(None)\n",
      "  File \"/home/hodei/anaconda3/envs/molmap/lib/python3.6/site-packages/IPython/core/interactiveshell.py\", line 3072, in run_cell_async\n",
      "    interactivity=interactivity, compiler=compiler, result=result)\n",
      "  File \"/home/hodei/anaconda3/envs/molmap/lib/python3.6/site-packages/IPython/core/interactiveshell.py\", line 3282, in run_ast_nodes\n",
      "    self.showtraceback()\n",
      "  File \"/home/hodei/anaconda3/envs/molmap/lib/python3.6/site-packages/IPython/core/interactiveshell.py\", line 2047, in showtraceback\n",
      "    value, tb, tb_offset=tb_offset)\n",
      "  File \"/home/hodei/anaconda3/envs/molmap/lib/python3.6/site-packages/IPython/core/ultratb.py\", line 1436, in structured_traceback\n",
      "    self, etype, value, tb, tb_offset, number_of_lines_of_context)\n",
      "  File \"/home/hodei/anaconda3/envs/molmap/lib/python3.6/site-packages/IPython/core/ultratb.py\", line 1336, in structured_traceback\n",
      "    self, etype, value, tb, tb_offset, number_of_lines_of_context\n",
      "  File \"/home/hodei/anaconda3/envs/molmap/lib/python3.6/site-packages/IPython/core/ultratb.py\", line 1211, in structured_traceback\n",
      "    chained_exceptions_tb_offset)\n",
      "  File \"/home/hodei/anaconda3/envs/molmap/lib/python3.6/site-packages/IPython/core/ultratb.py\", line 1150, in format_exception_as_a_whole\n",
      "    last_unique, recursion_repeat = find_recursion(orig_etype, evalue, records)\n",
      "  File \"/home/hodei/anaconda3/envs/molmap/lib/python3.6/site-packages/IPython/core/ultratb.py\", line 451, in find_recursion\n",
      "    return len(records), 0\n",
      "TypeError: object of type 'NoneType' has no len()\n",
      "\n",
      "During handling of the above exception, another exception occurred:\n",
      "\n",
      "Traceback (most recent call last):\n",
      "  File \"/home/hodei/anaconda3/envs/molmap/lib/python3.6/site-packages/IPython/core/interactiveshell.py\", line 2044, in showtraceback\n",
      "    stb = value._render_traceback_()\n",
      "AttributeError: 'TypeError' object has no attribute '_render_traceback_'\n",
      "\n",
      "During handling of the above exception, another exception occurred:\n",
      "\n",
      "Traceback (most recent call last):\n",
      "  File \"/home/hodei/anaconda3/envs/molmap/lib/python3.6/site-packages/IPython/core/ultratb.py\", line 1169, in get_records\n",
      "    return _fixed_getinnerframes(etb, number_of_lines_of_context, tb_offset)\n",
      "  File \"/home/hodei/anaconda3/envs/molmap/lib/python3.6/site-packages/IPython/core/ultratb.py\", line 316, in wrapped\n",
      "    return f(*args, **kwargs)\n",
      "  File \"/home/hodei/anaconda3/envs/molmap/lib/python3.6/site-packages/IPython/core/ultratb.py\", line 350, in _fixed_getinnerframes\n",
      "    records = fix_frame_records_filenames(inspect.getinnerframes(etb, context))\n",
      "  File \"/home/hodei/anaconda3/envs/molmap/lib/python3.6/inspect.py\", line 1490, in getinnerframes\n",
      "    frameinfo = (tb.tb_frame,) + getframeinfo(tb, context)\n",
      "  File \"/home/hodei/anaconda3/envs/molmap/lib/python3.6/inspect.py\", line 1448, in getframeinfo\n",
      "    filename = getsourcefile(frame) or getfile(frame)\n",
      "  File \"/home/hodei/anaconda3/envs/molmap/lib/python3.6/inspect.py\", line 696, in getsourcefile\n",
      "    if getattr(getmodule(object, filename), '__loader__', None) is not None:\n",
      "  File \"/home/hodei/anaconda3/envs/molmap/lib/python3.6/inspect.py\", line 733, in getmodule\n",
      "    if ismodule(module) and hasattr(module, '__file__'):\n",
      "  File \"/home/hodei/anaconda3/envs/molmap/lib/python3.6/site-packages/tensorflow/__init__.py\", line 50, in __getattr__\n",
      "    module = self._load()\n",
      "  File \"/home/hodei/anaconda3/envs/molmap/lib/python3.6/site-packages/tensorflow/__init__.py\", line 44, in _load\n",
      "    module = _importlib.import_module(self.__name__)\n",
      "  File \"/home/hodei/anaconda3/envs/molmap/lib/python3.6/importlib/__init__.py\", line 126, in import_module\n",
      "    return _bootstrap._gcd_import(name[level:], package, level)\n",
      "  File \"<frozen importlib._bootstrap>\", line 994, in _gcd_import\n",
      "  File \"<frozen importlib._bootstrap>\", line 971, in _find_and_load\n",
      "  File \"<frozen importlib._bootstrap>\", line 953, in _find_and_load_unlocked\n",
      "ModuleNotFoundError: No module named 'tensorflow_core.estimator'\n"
     ]
    }
   ],
   "source": [
    "print('Best epochs: %.2f, Best loss: %.2f' % (clf._performance.best_epoch, clf._performance.best))"
   ]
  },
  {
   "cell_type": "markdown",
   "metadata": {},
   "source": [
    "### Calibration curve"
   ]
  },
  {
   "cell_type": "code",
   "execution_count": null,
   "metadata": {},
   "outputs": [
    {
     "name": "stdout",
     "output_type": "stream",
     "text": [
      "ERROR! Session/line number was not unique in database. History logging moved to new session 3562\n"
     ]
    },
    {
     "name": "stderr",
     "output_type": "stream",
     "text": [
      "ERROR:root:Internal Python error in the inspect module.\n",
      "Below is the traceback from this internal error.\n",
      "\n",
      "ERROR:root:Internal Python error in the inspect module.\n",
      "Below is the traceback from this internal error.\n",
      "\n",
      "ERROR:root:Internal Python error in the inspect module.\n",
      "Below is the traceback from this internal error.\n",
      "\n"
     ]
    },
    {
     "name": "stdout",
     "output_type": "stream",
     "text": [
      "Traceback (most recent call last):\n",
      "  File \"/home/hodei/anaconda3/envs/molmap/lib/python3.6/site-packages/IPython/core/interactiveshell.py\", line 3343, in run_code\n",
      "    exec(code_obj, self.user_global_ns, self.user_ns)\n",
      "  File \"<ipython-input-7-657e920005a1>\", line 4, in <module>\n",
      "    df_pred = pd.DataFrame([testY[:, 1], clf.predict_proba(testX)[:,1]]).T\n",
      "  File \"/home/nuriacami/Documents/bidd-molmap/molmap/model/model.py\", line 513, in predict_proba\n",
      "    y_prob = self._model.predict(X)\n",
      "  File \"/home/hodei/anaconda3/envs/molmap/lib/python3.6/site-packages/tensorflow_core/python/keras/engine/training.py\", line 909, in predict\n",
      "    use_multiprocessing=use_multiprocessing)\n",
      "  File \"/home/hodei/anaconda3/envs/molmap/lib/python3.6/site-packages/tensorflow_core/python/keras/engine/training_v2.py\", line 462, in predict\n",
      "    steps=steps, callbacks=callbacks, **kwargs)\n",
      "  File \"/home/hodei/anaconda3/envs/molmap/lib/python3.6/site-packages/tensorflow_core/python/keras/engine/training_v2.py\", line 444, in _model_iteration\n",
      "    total_epochs=1)\n",
      "  File \"/home/hodei/anaconda3/envs/molmap/lib/python3.6/site-packages/tensorflow_core/python/keras/engine/training_v2.py\", line 123, in run_one_epoch\n",
      "    batch_outs = execution_function(iterator)\n",
      "  File \"/home/hodei/anaconda3/envs/molmap/lib/python3.6/site-packages/tensorflow_core/python/keras/engine/training_v2_utils.py\", line 86, in execution_function\n",
      "    distributed_function(input_fn))\n",
      "  File \"/home/hodei/anaconda3/envs/molmap/lib/python3.6/site-packages/tensorflow_core/python/eager/def_function.py\", line 457, in __call__\n",
      "    result = self._call(*args, **kwds)\n",
      "  File \"/home/hodei/anaconda3/envs/molmap/lib/python3.6/site-packages/tensorflow_core/python/eager/def_function.py\", line 494, in _call\n",
      "    results = self._stateful_fn(*args, **kwds)\n",
      "  File \"/home/hodei/anaconda3/envs/molmap/lib/python3.6/site-packages/tensorflow_core/python/eager/function.py\", line 1823, in __call__\n",
      "    return graph_function._filtered_call(args, kwargs)  # pylint: disable=protected-access\n",
      "  File \"/home/hodei/anaconda3/envs/molmap/lib/python3.6/site-packages/tensorflow_core/python/eager/function.py\", line 1141, in _filtered_call\n",
      "    self.captured_inputs)\n",
      "  File \"/home/hodei/anaconda3/envs/molmap/lib/python3.6/site-packages/tensorflow_core/python/eager/function.py\", line 1224, in _call_flat\n",
      "    ctx, args, cancellation_manager=cancellation_manager)\n",
      "  File \"/home/hodei/anaconda3/envs/molmap/lib/python3.6/site-packages/tensorflow_core/python/eager/function.py\", line 511, in call\n",
      "    ctx=ctx)\n",
      "  File \"/home/hodei/anaconda3/envs/molmap/lib/python3.6/site-packages/tensorflow_core/python/eager/execute.py\", line 67, in quick_execute\n",
      "    six.raise_from(core._status_to_exception(e.code, message), None)\n",
      "  File \"<string>\", line 3, in raise_from\n",
      "tensorflow.python.framework.errors_impl.UnknownError:  Failed to get convolution algorithm. This is probably because cuDNN failed to initialize, so try looking to see if a warning log message was printed above.\n",
      "\t [[node model/conv2d_7/Conv2D (defined at /home/hodei/anaconda3/envs/molmap/lib/python3.6/site-packages/tensorflow_core/python/framework/ops.py:1751) ]] [Op:__inference_distributed_function_2875]\n",
      "\n",
      "Function call stack:\n",
      "distributed_function\n",
      "\n",
      "\n",
      "During handling of the above exception, another exception occurred:\n",
      "\n",
      "Traceback (most recent call last):\n",
      "  File \"/home/hodei/anaconda3/envs/molmap/lib/python3.6/site-packages/IPython/core/interactiveshell.py\", line 2044, in showtraceback\n",
      "    stb = value._render_traceback_()\n",
      "AttributeError: 'UnknownError' object has no attribute '_render_traceback_'\n",
      "\n",
      "During handling of the above exception, another exception occurred:\n",
      "\n",
      "Traceback (most recent call last):\n",
      "  File \"/home/hodei/anaconda3/envs/molmap/lib/python3.6/site-packages/IPython/core/ultratb.py\", line 1169, in get_records\n",
      "    return _fixed_getinnerframes(etb, number_of_lines_of_context, tb_offset)\n",
      "  File \"/home/hodei/anaconda3/envs/molmap/lib/python3.6/site-packages/IPython/core/ultratb.py\", line 316, in wrapped\n",
      "    return f(*args, **kwargs)\n",
      "  File \"/home/hodei/anaconda3/envs/molmap/lib/python3.6/site-packages/IPython/core/ultratb.py\", line 350, in _fixed_getinnerframes\n",
      "    records = fix_frame_records_filenames(inspect.getinnerframes(etb, context))\n",
      "  File \"/home/hodei/anaconda3/envs/molmap/lib/python3.6/inspect.py\", line 1490, in getinnerframes\n",
      "    frameinfo = (tb.tb_frame,) + getframeinfo(tb, context)\n",
      "  File \"/home/hodei/anaconda3/envs/molmap/lib/python3.6/inspect.py\", line 1448, in getframeinfo\n",
      "    filename = getsourcefile(frame) or getfile(frame)\n",
      "  File \"/home/hodei/anaconda3/envs/molmap/lib/python3.6/inspect.py\", line 696, in getsourcefile\n",
      "    if getattr(getmodule(object, filename), '__loader__', None) is not None:\n",
      "  File \"/home/hodei/anaconda3/envs/molmap/lib/python3.6/inspect.py\", line 733, in getmodule\n",
      "    if ismodule(module) and hasattr(module, '__file__'):\n",
      "  File \"/home/hodei/anaconda3/envs/molmap/lib/python3.6/site-packages/tensorflow/__init__.py\", line 50, in __getattr__\n",
      "    module = self._load()\n",
      "  File \"/home/hodei/anaconda3/envs/molmap/lib/python3.6/site-packages/tensorflow/__init__.py\", line 44, in _load\n",
      "    module = _importlib.import_module(self.__name__)\n",
      "  File \"/home/hodei/anaconda3/envs/molmap/lib/python3.6/importlib/__init__.py\", line 126, in import_module\n",
      "    return _bootstrap._gcd_import(name[level:], package, level)\n",
      "  File \"<frozen importlib._bootstrap>\", line 994, in _gcd_import\n",
      "  File \"<frozen importlib._bootstrap>\", line 971, in _find_and_load\n",
      "  File \"<frozen importlib._bootstrap>\", line 953, in _find_and_load_unlocked\n",
      "ModuleNotFoundError: No module named 'tensorflow_core.estimator'\n",
      "Traceback (most recent call last):\n",
      "  File \"/home/hodei/anaconda3/envs/molmap/lib/python3.6/site-packages/IPython/core/interactiveshell.py\", line 3343, in run_code\n",
      "    exec(code_obj, self.user_global_ns, self.user_ns)\n",
      "  File \"<ipython-input-7-657e920005a1>\", line 4, in <module>\n",
      "    df_pred = pd.DataFrame([testY[:, 1], clf.predict_proba(testX)[:,1]]).T\n",
      "  File \"/home/nuriacami/Documents/bidd-molmap/molmap/model/model.py\", line 513, in predict_proba\n",
      "    y_prob = self._model.predict(X)\n",
      "  File \"/home/hodei/anaconda3/envs/molmap/lib/python3.6/site-packages/tensorflow_core/python/keras/engine/training.py\", line 909, in predict\n",
      "    use_multiprocessing=use_multiprocessing)\n",
      "  File \"/home/hodei/anaconda3/envs/molmap/lib/python3.6/site-packages/tensorflow_core/python/keras/engine/training_v2.py\", line 462, in predict\n",
      "    steps=steps, callbacks=callbacks, **kwargs)\n",
      "  File \"/home/hodei/anaconda3/envs/molmap/lib/python3.6/site-packages/tensorflow_core/python/keras/engine/training_v2.py\", line 444, in _model_iteration\n",
      "    total_epochs=1)\n",
      "  File \"/home/hodei/anaconda3/envs/molmap/lib/python3.6/site-packages/tensorflow_core/python/keras/engine/training_v2.py\", line 123, in run_one_epoch\n",
      "    batch_outs = execution_function(iterator)\n",
      "  File \"/home/hodei/anaconda3/envs/molmap/lib/python3.6/site-packages/tensorflow_core/python/keras/engine/training_v2_utils.py\", line 86, in execution_function\n",
      "    distributed_function(input_fn))\n",
      "  File \"/home/hodei/anaconda3/envs/molmap/lib/python3.6/site-packages/tensorflow_core/python/eager/def_function.py\", line 457, in __call__\n",
      "    result = self._call(*args, **kwds)\n",
      "  File \"/home/hodei/anaconda3/envs/molmap/lib/python3.6/site-packages/tensorflow_core/python/eager/def_function.py\", line 494, in _call\n",
      "    results = self._stateful_fn(*args, **kwds)\n",
      "  File \"/home/hodei/anaconda3/envs/molmap/lib/python3.6/site-packages/tensorflow_core/python/eager/function.py\", line 1823, in __call__\n",
      "    return graph_function._filtered_call(args, kwargs)  # pylint: disable=protected-access\n",
      "  File \"/home/hodei/anaconda3/envs/molmap/lib/python3.6/site-packages/tensorflow_core/python/eager/function.py\", line 1141, in _filtered_call\n",
      "    self.captured_inputs)\n",
      "  File \"/home/hodei/anaconda3/envs/molmap/lib/python3.6/site-packages/tensorflow_core/python/eager/function.py\", line 1224, in _call_flat\n",
      "    ctx, args, cancellation_manager=cancellation_manager)\n",
      "  File \"/home/hodei/anaconda3/envs/molmap/lib/python3.6/site-packages/tensorflow_core/python/eager/function.py\", line 511, in call\n",
      "    ctx=ctx)\n",
      "  File \"/home/hodei/anaconda3/envs/molmap/lib/python3.6/site-packages/tensorflow_core/python/eager/execute.py\", line 67, in quick_execute\n",
      "    six.raise_from(core._status_to_exception(e.code, message), None)\n",
      "  File \"<string>\", line 3, in raise_from\n",
      "tensorflow.python.framework.errors_impl.UnknownError:  Failed to get convolution algorithm. This is probably because cuDNN failed to initialize, so try looking to see if a warning log message was printed above.\n",
      "\t [[node model/conv2d_7/Conv2D (defined at /home/hodei/anaconda3/envs/molmap/lib/python3.6/site-packages/tensorflow_core/python/framework/ops.py:1751) ]] [Op:__inference_distributed_function_2875]\n",
      "\n",
      "Function call stack:\n",
      "distributed_function\n",
      "\n",
      "\n",
      "During handling of the above exception, another exception occurred:\n",
      "\n",
      "Traceback (most recent call last):\n",
      "  File \"/home/hodei/anaconda3/envs/molmap/lib/python3.6/site-packages/IPython/core/interactiveshell.py\", line 2044, in showtraceback\n",
      "    stb = value._render_traceback_()\n",
      "AttributeError: 'UnknownError' object has no attribute '_render_traceback_'\n",
      "\n",
      "During handling of the above exception, another exception occurred:\n",
      "\n",
      "Traceback (most recent call last):\n",
      "  File \"/home/hodei/anaconda3/envs/molmap/lib/python3.6/site-packages/IPython/core/interactiveshell.py\", line 3263, in run_ast_nodes\n",
      "    if (await self.run_code(code, result,  async_=asy)):\n",
      "  File \"/home/hodei/anaconda3/envs/molmap/lib/python3.6/site-packages/IPython/core/interactiveshell.py\", line 3360, in run_code\n",
      "    self.showtraceback(running_compiled_code=True)\n",
      "  File \"/home/hodei/anaconda3/envs/molmap/lib/python3.6/site-packages/IPython/core/interactiveshell.py\", line 2047, in showtraceback\n",
      "    value, tb, tb_offset=tb_offset)\n",
      "  File \"/home/hodei/anaconda3/envs/molmap/lib/python3.6/site-packages/IPython/core/ultratb.py\", line 1436, in structured_traceback\n",
      "    self, etype, value, tb, tb_offset, number_of_lines_of_context)\n",
      "  File \"/home/hodei/anaconda3/envs/molmap/lib/python3.6/site-packages/IPython/core/ultratb.py\", line 1336, in structured_traceback\n",
      "    self, etype, value, tb, tb_offset, number_of_lines_of_context\n",
      "  File \"/home/hodei/anaconda3/envs/molmap/lib/python3.6/site-packages/IPython/core/ultratb.py\", line 1193, in structured_traceback\n",
      "    tb_offset)\n",
      "  File \"/home/hodei/anaconda3/envs/molmap/lib/python3.6/site-packages/IPython/core/ultratb.py\", line 1150, in format_exception_as_a_whole\n",
      "    last_unique, recursion_repeat = find_recursion(orig_etype, evalue, records)\n",
      "  File \"/home/hodei/anaconda3/envs/molmap/lib/python3.6/site-packages/IPython/core/ultratb.py\", line 451, in find_recursion\n",
      "    return len(records), 0\n",
      "TypeError: object of type 'NoneType' has no len()\n",
      "\n",
      "During handling of the above exception, another exception occurred:\n",
      "\n",
      "Traceback (most recent call last):\n",
      "  File \"/home/hodei/anaconda3/envs/molmap/lib/python3.6/site-packages/IPython/core/interactiveshell.py\", line 2044, in showtraceback\n",
      "    stb = value._render_traceback_()\n",
      "AttributeError: 'TypeError' object has no attribute '_render_traceback_'\n",
      "\n",
      "During handling of the above exception, another exception occurred:\n",
      "\n",
      "Traceback (most recent call last):\n",
      "  File \"/home/hodei/anaconda3/envs/molmap/lib/python3.6/site-packages/IPython/core/ultratb.py\", line 1169, in get_records\n",
      "    return _fixed_getinnerframes(etb, number_of_lines_of_context, tb_offset)\n",
      "  File \"/home/hodei/anaconda3/envs/molmap/lib/python3.6/site-packages/IPython/core/ultratb.py\", line 316, in wrapped\n",
      "    return f(*args, **kwargs)\n",
      "  File \"/home/hodei/anaconda3/envs/molmap/lib/python3.6/site-packages/IPython/core/ultratb.py\", line 350, in _fixed_getinnerframes\n",
      "    records = fix_frame_records_filenames(inspect.getinnerframes(etb, context))\n",
      "  File \"/home/hodei/anaconda3/envs/molmap/lib/python3.6/inspect.py\", line 1490, in getinnerframes\n",
      "    frameinfo = (tb.tb_frame,) + getframeinfo(tb, context)\n",
      "  File \"/home/hodei/anaconda3/envs/molmap/lib/python3.6/inspect.py\", line 1448, in getframeinfo\n",
      "    filename = getsourcefile(frame) or getfile(frame)\n",
      "  File \"/home/hodei/anaconda3/envs/molmap/lib/python3.6/inspect.py\", line 696, in getsourcefile\n",
      "    if getattr(getmodule(object, filename), '__loader__', None) is not None:\n",
      "  File \"/home/hodei/anaconda3/envs/molmap/lib/python3.6/inspect.py\", line 733, in getmodule\n",
      "    if ismodule(module) and hasattr(module, '__file__'):\n",
      "  File \"/home/hodei/anaconda3/envs/molmap/lib/python3.6/site-packages/tensorflow/__init__.py\", line 50, in __getattr__\n",
      "    module = self._load()\n",
      "  File \"/home/hodei/anaconda3/envs/molmap/lib/python3.6/site-packages/tensorflow/__init__.py\", line 44, in _load\n",
      "    module = _importlib.import_module(self.__name__)\n",
      "  File \"/home/hodei/anaconda3/envs/molmap/lib/python3.6/importlib/__init__.py\", line 126, in import_module\n",
      "    return _bootstrap._gcd_import(name[level:], package, level)\n",
      "  File \"<frozen importlib._bootstrap>\", line 994, in _gcd_import\n",
      "  File \"<frozen importlib._bootstrap>\", line 971, in _find_and_load\n",
      "  File \"<frozen importlib._bootstrap>\", line 953, in _find_and_load_unlocked\n",
      "ModuleNotFoundError: No module named 'tensorflow_core.estimator'\n",
      "Traceback (most recent call last):\n",
      "  File \"/home/hodei/anaconda3/envs/molmap/lib/python3.6/site-packages/IPython/core/interactiveshell.py\", line 3343, in run_code\n",
      "    exec(code_obj, self.user_global_ns, self.user_ns)\n",
      "  File \"<ipython-input-7-657e920005a1>\", line 4, in <module>\n",
      "    df_pred = pd.DataFrame([testY[:, 1], clf.predict_proba(testX)[:,1]]).T\n",
      "  File \"/home/nuriacami/Documents/bidd-molmap/molmap/model/model.py\", line 513, in predict_proba\n",
      "    y_prob = self._model.predict(X)\n",
      "  File \"/home/hodei/anaconda3/envs/molmap/lib/python3.6/site-packages/tensorflow_core/python/keras/engine/training.py\", line 909, in predict\n",
      "    use_multiprocessing=use_multiprocessing)\n",
      "  File \"/home/hodei/anaconda3/envs/molmap/lib/python3.6/site-packages/tensorflow_core/python/keras/engine/training_v2.py\", line 462, in predict\n",
      "    steps=steps, callbacks=callbacks, **kwargs)\n",
      "  File \"/home/hodei/anaconda3/envs/molmap/lib/python3.6/site-packages/tensorflow_core/python/keras/engine/training_v2.py\", line 444, in _model_iteration\n",
      "    total_epochs=1)\n",
      "  File \"/home/hodei/anaconda3/envs/molmap/lib/python3.6/site-packages/tensorflow_core/python/keras/engine/training_v2.py\", line 123, in run_one_epoch\n",
      "    batch_outs = execution_function(iterator)\n",
      "  File \"/home/hodei/anaconda3/envs/molmap/lib/python3.6/site-packages/tensorflow_core/python/keras/engine/training_v2_utils.py\", line 86, in execution_function\n",
      "    distributed_function(input_fn))\n",
      "  File \"/home/hodei/anaconda3/envs/molmap/lib/python3.6/site-packages/tensorflow_core/python/eager/def_function.py\", line 457, in __call__\n",
      "    result = self._call(*args, **kwds)\n",
      "  File \"/home/hodei/anaconda3/envs/molmap/lib/python3.6/site-packages/tensorflow_core/python/eager/def_function.py\", line 494, in _call\n",
      "    results = self._stateful_fn(*args, **kwds)\n",
      "  File \"/home/hodei/anaconda3/envs/molmap/lib/python3.6/site-packages/tensorflow_core/python/eager/function.py\", line 1823, in __call__\n",
      "    return graph_function._filtered_call(args, kwargs)  # pylint: disable=protected-access\n",
      "  File \"/home/hodei/anaconda3/envs/molmap/lib/python3.6/site-packages/tensorflow_core/python/eager/function.py\", line 1141, in _filtered_call\n",
      "    self.captured_inputs)\n",
      "  File \"/home/hodei/anaconda3/envs/molmap/lib/python3.6/site-packages/tensorflow_core/python/eager/function.py\", line 1224, in _call_flat\n",
      "    ctx, args, cancellation_manager=cancellation_manager)\n",
      "  File \"/home/hodei/anaconda3/envs/molmap/lib/python3.6/site-packages/tensorflow_core/python/eager/function.py\", line 511, in call\n",
      "    ctx=ctx)\n",
      "  File \"/home/hodei/anaconda3/envs/molmap/lib/python3.6/site-packages/tensorflow_core/python/eager/execute.py\", line 67, in quick_execute\n",
      "    six.raise_from(core._status_to_exception(e.code, message), None)\n",
      "  File \"<string>\", line 3, in raise_from\n",
      "tensorflow.python.framework.errors_impl.UnknownError:  Failed to get convolution algorithm. This is probably because cuDNN failed to initialize, so try looking to see if a warning log message was printed above.\n",
      "\t [[node model/conv2d_7/Conv2D (defined at /home/hodei/anaconda3/envs/molmap/lib/python3.6/site-packages/tensorflow_core/python/framework/ops.py:1751) ]] [Op:__inference_distributed_function_2875]\n",
      "\n",
      "Function call stack:\n",
      "distributed_function\n",
      "\n",
      "\n",
      "During handling of the above exception, another exception occurred:\n",
      "\n",
      "Traceback (most recent call last):\n",
      "  File \"/home/hodei/anaconda3/envs/molmap/lib/python3.6/site-packages/IPython/core/interactiveshell.py\", line 2044, in showtraceback\n",
      "    stb = value._render_traceback_()\n",
      "AttributeError: 'UnknownError' object has no attribute '_render_traceback_'\n",
      "\n",
      "During handling of the above exception, another exception occurred:\n",
      "\n",
      "Traceback (most recent call last):\n",
      "  File \"/home/hodei/anaconda3/envs/molmap/lib/python3.6/site-packages/IPython/core/interactiveshell.py\", line 3263, in run_ast_nodes\n",
      "    if (await self.run_code(code, result,  async_=asy)):\n",
      "  File \"/home/hodei/anaconda3/envs/molmap/lib/python3.6/site-packages/IPython/core/interactiveshell.py\", line 3360, in run_code\n",
      "    self.showtraceback(running_compiled_code=True)\n",
      "  File \"/home/hodei/anaconda3/envs/molmap/lib/python3.6/site-packages/IPython/core/interactiveshell.py\", line 2047, in showtraceback\n",
      "    value, tb, tb_offset=tb_offset)\n",
      "  File \"/home/hodei/anaconda3/envs/molmap/lib/python3.6/site-packages/IPython/core/ultratb.py\", line 1436, in structured_traceback\n",
      "    self, etype, value, tb, tb_offset, number_of_lines_of_context)\n",
      "  File \"/home/hodei/anaconda3/envs/molmap/lib/python3.6/site-packages/IPython/core/ultratb.py\", line 1336, in structured_traceback\n",
      "    self, etype, value, tb, tb_offset, number_of_lines_of_context\n",
      "  File \"/home/hodei/anaconda3/envs/molmap/lib/python3.6/site-packages/IPython/core/ultratb.py\", line 1193, in structured_traceback\n",
      "    tb_offset)\n",
      "  File \"/home/hodei/anaconda3/envs/molmap/lib/python3.6/site-packages/IPython/core/ultratb.py\", line 1150, in format_exception_as_a_whole\n",
      "    last_unique, recursion_repeat = find_recursion(orig_etype, evalue, records)\n",
      "  File \"/home/hodei/anaconda3/envs/molmap/lib/python3.6/site-packages/IPython/core/ultratb.py\", line 451, in find_recursion\n",
      "    return len(records), 0\n",
      "TypeError: object of type 'NoneType' has no len()\n",
      "\n",
      "During handling of the above exception, another exception occurred:\n",
      "\n",
      "Traceback (most recent call last):\n",
      "  File \"/home/hodei/anaconda3/envs/molmap/lib/python3.6/site-packages/IPython/core/interactiveshell.py\", line 2044, in showtraceback\n",
      "    stb = value._render_traceback_()\n",
      "AttributeError: 'TypeError' object has no attribute '_render_traceback_'\n",
      "\n",
      "During handling of the above exception, another exception occurred:\n",
      "\n",
      "Traceback (most recent call last):\n",
      "  File \"/home/hodei/anaconda3/envs/molmap/lib/python3.6/site-packages/IPython/core/interactiveshell.py\", line 2895, in _run_cell\n",
      "    return runner(coro)\n",
      "  File \"/home/hodei/anaconda3/envs/molmap/lib/python3.6/site-packages/IPython/core/async_helpers.py\", line 68, in _pseudo_sync_runner\n",
      "    coro.send(None)\n",
      "  File \"/home/hodei/anaconda3/envs/molmap/lib/python3.6/site-packages/IPython/core/interactiveshell.py\", line 3072, in run_cell_async\n",
      "    interactivity=interactivity, compiler=compiler, result=result)\n",
      "  File \"/home/hodei/anaconda3/envs/molmap/lib/python3.6/site-packages/IPython/core/interactiveshell.py\", line 3282, in run_ast_nodes\n",
      "    self.showtraceback()\n",
      "  File \"/home/hodei/anaconda3/envs/molmap/lib/python3.6/site-packages/IPython/core/interactiveshell.py\", line 2047, in showtraceback\n",
      "    value, tb, tb_offset=tb_offset)\n",
      "  File \"/home/hodei/anaconda3/envs/molmap/lib/python3.6/site-packages/IPython/core/ultratb.py\", line 1436, in structured_traceback\n",
      "    self, etype, value, tb, tb_offset, number_of_lines_of_context)\n",
      "  File \"/home/hodei/anaconda3/envs/molmap/lib/python3.6/site-packages/IPython/core/ultratb.py\", line 1336, in structured_traceback\n",
      "    self, etype, value, tb, tb_offset, number_of_lines_of_context\n",
      "  File \"/home/hodei/anaconda3/envs/molmap/lib/python3.6/site-packages/IPython/core/ultratb.py\", line 1211, in structured_traceback\n",
      "    chained_exceptions_tb_offset)\n",
      "  File \"/home/hodei/anaconda3/envs/molmap/lib/python3.6/site-packages/IPython/core/ultratb.py\", line 1150, in format_exception_as_a_whole\n",
      "    last_unique, recursion_repeat = find_recursion(orig_etype, evalue, records)\n",
      "  File \"/home/hodei/anaconda3/envs/molmap/lib/python3.6/site-packages/IPython/core/ultratb.py\", line 451, in find_recursion\n",
      "    return len(records), 0\n",
      "TypeError: object of type 'NoneType' has no len()\n",
      "\n",
      "During handling of the above exception, another exception occurred:\n",
      "\n",
      "Traceback (most recent call last):\n",
      "  File \"/home/hodei/anaconda3/envs/molmap/lib/python3.6/site-packages/IPython/core/interactiveshell.py\", line 2044, in showtraceback\n",
      "    stb = value._render_traceback_()\n",
      "AttributeError: 'TypeError' object has no attribute '_render_traceback_'\n",
      "\n",
      "During handling of the above exception, another exception occurred:\n",
      "\n",
      "Traceback (most recent call last):\n",
      "  File \"/home/hodei/anaconda3/envs/molmap/lib/python3.6/site-packages/IPython/core/ultratb.py\", line 1169, in get_records\n",
      "    return _fixed_getinnerframes(etb, number_of_lines_of_context, tb_offset)\n",
      "  File \"/home/hodei/anaconda3/envs/molmap/lib/python3.6/site-packages/IPython/core/ultratb.py\", line 316, in wrapped\n",
      "    return f(*args, **kwargs)\n",
      "  File \"/home/hodei/anaconda3/envs/molmap/lib/python3.6/site-packages/IPython/core/ultratb.py\", line 350, in _fixed_getinnerframes\n",
      "    records = fix_frame_records_filenames(inspect.getinnerframes(etb, context))\n",
      "  File \"/home/hodei/anaconda3/envs/molmap/lib/python3.6/inspect.py\", line 1490, in getinnerframes\n",
      "    frameinfo = (tb.tb_frame,) + getframeinfo(tb, context)\n",
      "  File \"/home/hodei/anaconda3/envs/molmap/lib/python3.6/inspect.py\", line 1448, in getframeinfo\n",
      "    filename = getsourcefile(frame) or getfile(frame)\n",
      "  File \"/home/hodei/anaconda3/envs/molmap/lib/python3.6/inspect.py\", line 696, in getsourcefile\n",
      "    if getattr(getmodule(object, filename), '__loader__', None) is not None:\n",
      "  File \"/home/hodei/anaconda3/envs/molmap/lib/python3.6/inspect.py\", line 733, in getmodule\n",
      "    if ismodule(module) and hasattr(module, '__file__'):\n",
      "  File \"/home/hodei/anaconda3/envs/molmap/lib/python3.6/site-packages/tensorflow/__init__.py\", line 50, in __getattr__\n",
      "    module = self._load()\n",
      "  File \"/home/hodei/anaconda3/envs/molmap/lib/python3.6/site-packages/tensorflow/__init__.py\", line 44, in _load\n",
      "    module = _importlib.import_module(self.__name__)\n",
      "  File \"/home/hodei/anaconda3/envs/molmap/lib/python3.6/importlib/__init__.py\", line 126, in import_module\n",
      "    return _bootstrap._gcd_import(name[level:], package, level)\n",
      "  File \"<frozen importlib._bootstrap>\", line 994, in _gcd_import\n",
      "  File \"<frozen importlib._bootstrap>\", line 971, in _find_and_load\n",
      "  File \"<frozen importlib._bootstrap>\", line 953, in _find_and_load_unlocked\n",
      "ModuleNotFoundError: No module named 'tensorflow_core.estimator'\n"
     ]
    }
   ],
   "source": [
    "import matplotlib.pyplot as plt\n",
    "\n",
    "# predict probabilities\n",
    "df_pred = pd.DataFrame([testY[:, 1], clf.predict_proba(testX)[:,1]]).T\n",
    "df_pred.columns=['y_true', 'y_pred_prob']\n",
    "\n",
    "# distributions for each class\n",
    "dist0 = df_pred[df_pred['y_true'] == 0]['y_pred_prob'].tolist()\n",
    "dist1 = df_pred[df_pred['y_true'] == 1]['y_pred_prob'].tolist()\n",
    "\n",
    "# plot\n",
    "plt.figure(figsize=(16, 4))\n",
    "plt.title('Predicted probabilities distribution for each class')\n",
    "plt.hist(dist0,histtype='step', label=\"Inactive (0)\", color='r')  \n",
    "plt.hist(dist1,histtype='step', label=\"Active (1)\", color='g')\n",
    "plt.xlabel('Predicted probability')\n",
    "plt.ylabel('Counts')\n",
    "plt.legend()\n",
    "plt.show()"
   ]
  },
  {
   "cell_type": "code",
   "execution_count": null,
   "metadata": {},
   "outputs": [
    {
     "name": "stderr",
     "output_type": "stream",
     "text": [
      "ERROR:root:Internal Python error in the inspect module.\n",
      "Below is the traceback from this internal error.\n",
      "\n",
      "ERROR:root:Internal Python error in the inspect module.\n",
      "Below is the traceback from this internal error.\n",
      "\n",
      "ERROR:root:Internal Python error in the inspect module.\n",
      "Below is the traceback from this internal error.\n",
      "\n"
     ]
    },
    {
     "name": "stdout",
     "output_type": "stream",
     "text": [
      "Traceback (most recent call last):\n",
      "  File \"/home/hodei/anaconda3/envs/molmap/lib/python3.6/site-packages/IPython/core/interactiveshell.py\", line 3343, in run_code\n",
      "    exec(code_obj, self.user_global_ns, self.user_ns)\n",
      "  File \"<ipython-input-7-0d6d77a3ebf6>\", line 4, in <module>\n",
      "    fop, mpv = calibration_curve(df_pred['y_true'], df_pred['y_pred_prob'], n_bins=10)\n",
      "NameError: name 'df_pred' is not defined\n",
      "\n",
      "During handling of the above exception, another exception occurred:\n",
      "\n",
      "Traceback (most recent call last):\n",
      "  File \"/home/hodei/anaconda3/envs/molmap/lib/python3.6/site-packages/IPython/core/interactiveshell.py\", line 2044, in showtraceback\n",
      "    stb = value._render_traceback_()\n",
      "AttributeError: 'NameError' object has no attribute '_render_traceback_'\n",
      "\n",
      "During handling of the above exception, another exception occurred:\n",
      "\n",
      "Traceback (most recent call last):\n",
      "  File \"/home/hodei/anaconda3/envs/molmap/lib/python3.6/site-packages/IPython/core/ultratb.py\", line 1169, in get_records\n",
      "    return _fixed_getinnerframes(etb, number_of_lines_of_context, tb_offset)\n",
      "  File \"/home/hodei/anaconda3/envs/molmap/lib/python3.6/site-packages/IPython/core/ultratb.py\", line 316, in wrapped\n",
      "    return f(*args, **kwargs)\n",
      "  File \"/home/hodei/anaconda3/envs/molmap/lib/python3.6/site-packages/IPython/core/ultratb.py\", line 350, in _fixed_getinnerframes\n",
      "    records = fix_frame_records_filenames(inspect.getinnerframes(etb, context))\n",
      "  File \"/home/hodei/anaconda3/envs/molmap/lib/python3.6/inspect.py\", line 1490, in getinnerframes\n",
      "    frameinfo = (tb.tb_frame,) + getframeinfo(tb, context)\n",
      "  File \"/home/hodei/anaconda3/envs/molmap/lib/python3.6/inspect.py\", line 1448, in getframeinfo\n",
      "    filename = getsourcefile(frame) or getfile(frame)\n",
      "  File \"/home/hodei/anaconda3/envs/molmap/lib/python3.6/inspect.py\", line 696, in getsourcefile\n",
      "    if getattr(getmodule(object, filename), '__loader__', None) is not None:\n",
      "  File \"/home/hodei/anaconda3/envs/molmap/lib/python3.6/inspect.py\", line 733, in getmodule\n",
      "    if ismodule(module) and hasattr(module, '__file__'):\n",
      "  File \"/home/hodei/anaconda3/envs/molmap/lib/python3.6/site-packages/tensorflow/__init__.py\", line 50, in __getattr__\n",
      "    module = self._load()\n",
      "  File \"/home/hodei/anaconda3/envs/molmap/lib/python3.6/site-packages/tensorflow/__init__.py\", line 44, in _load\n",
      "    module = _importlib.import_module(self.__name__)\n",
      "  File \"/home/hodei/anaconda3/envs/molmap/lib/python3.6/importlib/__init__.py\", line 126, in import_module\n",
      "    return _bootstrap._gcd_import(name[level:], package, level)\n",
      "  File \"<frozen importlib._bootstrap>\", line 994, in _gcd_import\n",
      "  File \"<frozen importlib._bootstrap>\", line 971, in _find_and_load\n",
      "  File \"<frozen importlib._bootstrap>\", line 953, in _find_and_load_unlocked\n",
      "ModuleNotFoundError: No module named 'tensorflow_core.estimator'\n",
      "ERROR! Session/line number was not unique in database. History logging moved to new session 3563\n",
      "Traceback (most recent call last):\n",
      "  File \"/home/hodei/anaconda3/envs/molmap/lib/python3.6/site-packages/IPython/core/interactiveshell.py\", line 3343, in run_code\n",
      "    exec(code_obj, self.user_global_ns, self.user_ns)\n",
      "  File \"<ipython-input-7-0d6d77a3ebf6>\", line 4, in <module>\n",
      "    fop, mpv = calibration_curve(df_pred['y_true'], df_pred['y_pred_prob'], n_bins=10)\n",
      "NameError: name 'df_pred' is not defined\n",
      "\n",
      "During handling of the above exception, another exception occurred:\n",
      "\n",
      "Traceback (most recent call last):\n",
      "  File \"/home/hodei/anaconda3/envs/molmap/lib/python3.6/site-packages/IPython/core/interactiveshell.py\", line 2044, in showtraceback\n",
      "    stb = value._render_traceback_()\n",
      "AttributeError: 'NameError' object has no attribute '_render_traceback_'\n",
      "\n",
      "During handling of the above exception, another exception occurred:\n",
      "\n",
      "Traceback (most recent call last):\n",
      "  File \"/home/hodei/anaconda3/envs/molmap/lib/python3.6/site-packages/IPython/core/interactiveshell.py\", line 3263, in run_ast_nodes\n",
      "    if (await self.run_code(code, result,  async_=asy)):\n",
      "  File \"/home/hodei/anaconda3/envs/molmap/lib/python3.6/site-packages/IPython/core/interactiveshell.py\", line 3360, in run_code\n",
      "    self.showtraceback(running_compiled_code=True)\n",
      "  File \"/home/hodei/anaconda3/envs/molmap/lib/python3.6/site-packages/IPython/core/interactiveshell.py\", line 2047, in showtraceback\n",
      "    value, tb, tb_offset=tb_offset)\n",
      "  File \"/home/hodei/anaconda3/envs/molmap/lib/python3.6/site-packages/IPython/core/ultratb.py\", line 1436, in structured_traceback\n",
      "    self, etype, value, tb, tb_offset, number_of_lines_of_context)\n",
      "  File \"/home/hodei/anaconda3/envs/molmap/lib/python3.6/site-packages/IPython/core/ultratb.py\", line 1336, in structured_traceback\n",
      "    self, etype, value, tb, tb_offset, number_of_lines_of_context\n",
      "  File \"/home/hodei/anaconda3/envs/molmap/lib/python3.6/site-packages/IPython/core/ultratb.py\", line 1193, in structured_traceback\n",
      "    tb_offset)\n",
      "  File \"/home/hodei/anaconda3/envs/molmap/lib/python3.6/site-packages/IPython/core/ultratb.py\", line 1150, in format_exception_as_a_whole\n",
      "    last_unique, recursion_repeat = find_recursion(orig_etype, evalue, records)\n",
      "  File \"/home/hodei/anaconda3/envs/molmap/lib/python3.6/site-packages/IPython/core/ultratb.py\", line 451, in find_recursion\n",
      "    return len(records), 0\n",
      "TypeError: object of type 'NoneType' has no len()\n",
      "\n",
      "During handling of the above exception, another exception occurred:\n",
      "\n",
      "Traceback (most recent call last):\n",
      "  File \"/home/hodei/anaconda3/envs/molmap/lib/python3.6/site-packages/IPython/core/interactiveshell.py\", line 2044, in showtraceback\n",
      "    stb = value._render_traceback_()\n",
      "AttributeError: 'TypeError' object has no attribute '_render_traceback_'\n",
      "\n",
      "During handling of the above exception, another exception occurred:\n",
      "\n",
      "Traceback (most recent call last):\n",
      "  File \"/home/hodei/anaconda3/envs/molmap/lib/python3.6/site-packages/IPython/core/ultratb.py\", line 1169, in get_records\n",
      "    return _fixed_getinnerframes(etb, number_of_lines_of_context, tb_offset)\n",
      "  File \"/home/hodei/anaconda3/envs/molmap/lib/python3.6/site-packages/IPython/core/ultratb.py\", line 316, in wrapped\n",
      "    return f(*args, **kwargs)\n",
      "  File \"/home/hodei/anaconda3/envs/molmap/lib/python3.6/site-packages/IPython/core/ultratb.py\", line 350, in _fixed_getinnerframes\n",
      "    records = fix_frame_records_filenames(inspect.getinnerframes(etb, context))\n",
      "  File \"/home/hodei/anaconda3/envs/molmap/lib/python3.6/inspect.py\", line 1490, in getinnerframes\n",
      "    frameinfo = (tb.tb_frame,) + getframeinfo(tb, context)\n",
      "  File \"/home/hodei/anaconda3/envs/molmap/lib/python3.6/inspect.py\", line 1448, in getframeinfo\n",
      "    filename = getsourcefile(frame) or getfile(frame)\n",
      "  File \"/home/hodei/anaconda3/envs/molmap/lib/python3.6/inspect.py\", line 696, in getsourcefile\n",
      "    if getattr(getmodule(object, filename), '__loader__', None) is not None:\n",
      "  File \"/home/hodei/anaconda3/envs/molmap/lib/python3.6/inspect.py\", line 733, in getmodule\n",
      "    if ismodule(module) and hasattr(module, '__file__'):\n",
      "  File \"/home/hodei/anaconda3/envs/molmap/lib/python3.6/site-packages/tensorflow/__init__.py\", line 50, in __getattr__\n",
      "    module = self._load()\n",
      "  File \"/home/hodei/anaconda3/envs/molmap/lib/python3.6/site-packages/tensorflow/__init__.py\", line 44, in _load\n",
      "    module = _importlib.import_module(self.__name__)\n",
      "  File \"/home/hodei/anaconda3/envs/molmap/lib/python3.6/importlib/__init__.py\", line 126, in import_module\n",
      "    return _bootstrap._gcd_import(name[level:], package, level)\n",
      "  File \"<frozen importlib._bootstrap>\", line 994, in _gcd_import\n",
      "  File \"<frozen importlib._bootstrap>\", line 971, in _find_and_load\n",
      "  File \"<frozen importlib._bootstrap>\", line 953, in _find_and_load_unlocked\n",
      "ModuleNotFoundError: No module named 'tensorflow_core.estimator'\n",
      "Traceback (most recent call last):\n",
      "  File \"/home/hodei/anaconda3/envs/molmap/lib/python3.6/site-packages/IPython/core/interactiveshell.py\", line 3343, in run_code\n",
      "    exec(code_obj, self.user_global_ns, self.user_ns)\n",
      "  File \"<ipython-input-7-0d6d77a3ebf6>\", line 4, in <module>\n",
      "    fop, mpv = calibration_curve(df_pred['y_true'], df_pred['y_pred_prob'], n_bins=10)\n",
      "NameError: name 'df_pred' is not defined\n",
      "\n",
      "During handling of the above exception, another exception occurred:\n",
      "\n",
      "Traceback (most recent call last):\n",
      "  File \"/home/hodei/anaconda3/envs/molmap/lib/python3.6/site-packages/IPython/core/interactiveshell.py\", line 2044, in showtraceback\n",
      "    stb = value._render_traceback_()\n",
      "AttributeError: 'NameError' object has no attribute '_render_traceback_'\n",
      "\n",
      "During handling of the above exception, another exception occurred:\n",
      "\n",
      "Traceback (most recent call last):\n",
      "  File \"/home/hodei/anaconda3/envs/molmap/lib/python3.6/site-packages/IPython/core/interactiveshell.py\", line 3263, in run_ast_nodes\n",
      "    if (await self.run_code(code, result,  async_=asy)):\n",
      "  File \"/home/hodei/anaconda3/envs/molmap/lib/python3.6/site-packages/IPython/core/interactiveshell.py\", line 3360, in run_code\n",
      "    self.showtraceback(running_compiled_code=True)\n",
      "  File \"/home/hodei/anaconda3/envs/molmap/lib/python3.6/site-packages/IPython/core/interactiveshell.py\", line 2047, in showtraceback\n",
      "    value, tb, tb_offset=tb_offset)\n",
      "  File \"/home/hodei/anaconda3/envs/molmap/lib/python3.6/site-packages/IPython/core/ultratb.py\", line 1436, in structured_traceback\n",
      "    self, etype, value, tb, tb_offset, number_of_lines_of_context)\n",
      "  File \"/home/hodei/anaconda3/envs/molmap/lib/python3.6/site-packages/IPython/core/ultratb.py\", line 1336, in structured_traceback\n",
      "    self, etype, value, tb, tb_offset, number_of_lines_of_context\n",
      "  File \"/home/hodei/anaconda3/envs/molmap/lib/python3.6/site-packages/IPython/core/ultratb.py\", line 1193, in structured_traceback\n",
      "    tb_offset)\n",
      "  File \"/home/hodei/anaconda3/envs/molmap/lib/python3.6/site-packages/IPython/core/ultratb.py\", line 1150, in format_exception_as_a_whole\n",
      "    last_unique, recursion_repeat = find_recursion(orig_etype, evalue, records)\n",
      "  File \"/home/hodei/anaconda3/envs/molmap/lib/python3.6/site-packages/IPython/core/ultratb.py\", line 451, in find_recursion\n",
      "    return len(records), 0\n",
      "TypeError: object of type 'NoneType' has no len()\n",
      "\n",
      "During handling of the above exception, another exception occurred:\n",
      "\n",
      "Traceback (most recent call last):\n",
      "  File \"/home/hodei/anaconda3/envs/molmap/lib/python3.6/site-packages/IPython/core/interactiveshell.py\", line 2044, in showtraceback\n",
      "    stb = value._render_traceback_()\n",
      "AttributeError: 'TypeError' object has no attribute '_render_traceback_'\n",
      "\n",
      "During handling of the above exception, another exception occurred:\n",
      "\n",
      "Traceback (most recent call last):\n",
      "  File \"/home/hodei/anaconda3/envs/molmap/lib/python3.6/site-packages/IPython/core/interactiveshell.py\", line 2895, in _run_cell\n",
      "    return runner(coro)\n",
      "  File \"/home/hodei/anaconda3/envs/molmap/lib/python3.6/site-packages/IPython/core/async_helpers.py\", line 68, in _pseudo_sync_runner\n",
      "    coro.send(None)\n",
      "  File \"/home/hodei/anaconda3/envs/molmap/lib/python3.6/site-packages/IPython/core/interactiveshell.py\", line 3072, in run_cell_async\n",
      "    interactivity=interactivity, compiler=compiler, result=result)\n",
      "  File \"/home/hodei/anaconda3/envs/molmap/lib/python3.6/site-packages/IPython/core/interactiveshell.py\", line 3282, in run_ast_nodes\n",
      "    self.showtraceback()\n",
      "  File \"/home/hodei/anaconda3/envs/molmap/lib/python3.6/site-packages/IPython/core/interactiveshell.py\", line 2047, in showtraceback\n",
      "    value, tb, tb_offset=tb_offset)\n",
      "  File \"/home/hodei/anaconda3/envs/molmap/lib/python3.6/site-packages/IPython/core/ultratb.py\", line 1436, in structured_traceback\n",
      "    self, etype, value, tb, tb_offset, number_of_lines_of_context)\n",
      "  File \"/home/hodei/anaconda3/envs/molmap/lib/python3.6/site-packages/IPython/core/ultratb.py\", line 1336, in structured_traceback\n",
      "    self, etype, value, tb, tb_offset, number_of_lines_of_context\n",
      "  File \"/home/hodei/anaconda3/envs/molmap/lib/python3.6/site-packages/IPython/core/ultratb.py\", line 1211, in structured_traceback\n",
      "    chained_exceptions_tb_offset)\n",
      "  File \"/home/hodei/anaconda3/envs/molmap/lib/python3.6/site-packages/IPython/core/ultratb.py\", line 1150, in format_exception_as_a_whole\n",
      "    last_unique, recursion_repeat = find_recursion(orig_etype, evalue, records)\n",
      "  File \"/home/hodei/anaconda3/envs/molmap/lib/python3.6/site-packages/IPython/core/ultratb.py\", line 451, in find_recursion\n",
      "    return len(records), 0\n",
      "TypeError: object of type 'NoneType' has no len()\n",
      "\n",
      "During handling of the above exception, another exception occurred:\n",
      "\n",
      "Traceback (most recent call last):\n",
      "  File \"/home/hodei/anaconda3/envs/molmap/lib/python3.6/site-packages/IPython/core/interactiveshell.py\", line 2044, in showtraceback\n",
      "    stb = value._render_traceback_()\n",
      "AttributeError: 'TypeError' object has no attribute '_render_traceback_'\n",
      "\n",
      "During handling of the above exception, another exception occurred:\n",
      "\n",
      "Traceback (most recent call last):\n",
      "  File \"/home/hodei/anaconda3/envs/molmap/lib/python3.6/site-packages/IPython/core/ultratb.py\", line 1169, in get_records\n",
      "    return _fixed_getinnerframes(etb, number_of_lines_of_context, tb_offset)\n",
      "  File \"/home/hodei/anaconda3/envs/molmap/lib/python3.6/site-packages/IPython/core/ultratb.py\", line 316, in wrapped\n",
      "    return f(*args, **kwargs)\n",
      "  File \"/home/hodei/anaconda3/envs/molmap/lib/python3.6/site-packages/IPython/core/ultratb.py\", line 350, in _fixed_getinnerframes\n",
      "    records = fix_frame_records_filenames(inspect.getinnerframes(etb, context))\n",
      "  File \"/home/hodei/anaconda3/envs/molmap/lib/python3.6/inspect.py\", line 1490, in getinnerframes\n",
      "    frameinfo = (tb.tb_frame,) + getframeinfo(tb, context)\n",
      "  File \"/home/hodei/anaconda3/envs/molmap/lib/python3.6/inspect.py\", line 1448, in getframeinfo\n",
      "    filename = getsourcefile(frame) or getfile(frame)\n",
      "  File \"/home/hodei/anaconda3/envs/molmap/lib/python3.6/inspect.py\", line 696, in getsourcefile\n",
      "    if getattr(getmodule(object, filename), '__loader__', None) is not None:\n",
      "  File \"/home/hodei/anaconda3/envs/molmap/lib/python3.6/inspect.py\", line 733, in getmodule\n",
      "    if ismodule(module) and hasattr(module, '__file__'):\n",
      "  File \"/home/hodei/anaconda3/envs/molmap/lib/python3.6/site-packages/tensorflow/__init__.py\", line 50, in __getattr__\n",
      "    module = self._load()\n",
      "  File \"/home/hodei/anaconda3/envs/molmap/lib/python3.6/site-packages/tensorflow/__init__.py\", line 44, in _load\n",
      "    module = _importlib.import_module(self.__name__)\n",
      "  File \"/home/hodei/anaconda3/envs/molmap/lib/python3.6/importlib/__init__.py\", line 126, in import_module\n",
      "    return _bootstrap._gcd_import(name[level:], package, level)\n",
      "  File \"<frozen importlib._bootstrap>\", line 994, in _gcd_import\n",
      "  File \"<frozen importlib._bootstrap>\", line 971, in _find_and_load\n",
      "  File \"<frozen importlib._bootstrap>\", line 953, in _find_and_load_unlocked\n",
      "ModuleNotFoundError: No module named 'tensorflow_core.estimator'\n"
     ]
    }
   ],
   "source": [
    "from sklearn.calibration import calibration_curve\n",
    "\n",
    "# reliability diagram\n",
    "fop, mpv = calibration_curve(df_pred['y_true'], df_pred['y_pred_prob'], n_bins=10)\n",
    "\n",
    "# plot perfectly calibrated\n",
    "plt.plot([0, 1], [0, 1], linestyle='--', c='cadetblue')\n",
    "\n",
    "# plot model reliability\n",
    "plt.title('Calibration curve')\n",
    "plt.plot(mpv, fop, marker='.', c='deeppink')\n",
    "plt.xlabel('Mean predicted probability (Positive class:1)')\n",
    "plt.ylabel('Fraction of positives (Positive class:1)')\n",
    "plt.show()"
   ]
  },
  {
   "cell_type": "markdown",
   "metadata": {},
   "source": [
    "### Evaluation on test set: AUC"
   ]
  },
  {
   "cell_type": "code",
   "execution_count": null,
   "metadata": {},
   "outputs": [
    {
     "name": "stderr",
     "output_type": "stream",
     "text": [
      "ERROR:root:Internal Python error in the inspect module.\n",
      "Below is the traceback from this internal error.\n",
      "\n"
     ]
    },
    {
     "name": "stdout",
     "output_type": "stream",
     "text": [
      "Traceback (most recent call last):\n",
      "  File \"/home/hodei/anaconda3/envs/molmap/lib/python3.6/site-packages/IPython/core/interactiveshell.py\", line 3343, in run_code\n",
      "    exec(code_obj, self.user_global_ns, self.user_ns)\n",
      "  File \"<ipython-input-7-1883fbc42122>\", line 1, in <module>\n",
      "    auc = clf.score(testX, testY)\n",
      "  File \"/home/nuriacami/Documents/bidd-molmap/molmap/model/model.py\", line 544, in score\n",
      "    metrics = self._performance.evaluate(X, y)\n",
      "AttributeError: 'MultiClassEstimator' object has no attribute '_performance'\n",
      "\n",
      "During handling of the above exception, another exception occurred:\n",
      "\n",
      "Traceback (most recent call last):\n",
      "  File \"/home/hodei/anaconda3/envs/molmap/lib/python3.6/site-packages/IPython/core/interactiveshell.py\", line 2044, in showtraceback\n",
      "    stb = value._render_traceback_()\n",
      "AttributeError: 'AttributeError' object has no attribute '_render_traceback_'\n",
      "\n",
      "During handling of the above exception, another exception occurred:\n",
      "\n",
      "Traceback (most recent call last):\n",
      "  File \"/home/hodei/anaconda3/envs/molmap/lib/python3.6/site-packages/IPython/core/ultratb.py\", line 1169, in get_records\n",
      "    return _fixed_getinnerframes(etb, number_of_lines_of_context, tb_offset)\n"
     ]
    },
    {
     "name": "stderr",
     "output_type": "stream",
     "text": [
      "ERROR:root:Internal Python error in the inspect module.\n",
      "Below is the traceback from this internal error.\n",
      "\n",
      "ERROR:root:Internal Python error in the inspect module.\n",
      "Below is the traceback from this internal error.\n",
      "\n"
     ]
    },
    {
     "name": "stdout",
     "output_type": "stream",
     "text": [
      "  File \"/home/hodei/anaconda3/envs/molmap/lib/python3.6/site-packages/IPython/core/ultratb.py\", line 316, in wrapped\n",
      "    return f(*args, **kwargs)\n",
      "  File \"/home/hodei/anaconda3/envs/molmap/lib/python3.6/site-packages/IPython/core/ultratb.py\", line 350, in _fixed_getinnerframes\n",
      "    records = fix_frame_records_filenames(inspect.getinnerframes(etb, context))\n",
      "  File \"/home/hodei/anaconda3/envs/molmap/lib/python3.6/inspect.py\", line 1490, in getinnerframes\n",
      "    frameinfo = (tb.tb_frame,) + getframeinfo(tb, context)\n",
      "  File \"/home/hodei/anaconda3/envs/molmap/lib/python3.6/inspect.py\", line 1448, in getframeinfo\n",
      "    filename = getsourcefile(frame) or getfile(frame)\n",
      "  File \"/home/hodei/anaconda3/envs/molmap/lib/python3.6/inspect.py\", line 696, in getsourcefile\n",
      "    if getattr(getmodule(object, filename), '__loader__', None) is not None:\n",
      "  File \"/home/hodei/anaconda3/envs/molmap/lib/python3.6/inspect.py\", line 733, in getmodule\n",
      "    if ismodule(module) and hasattr(module, '__file__'):\n",
      "  File \"/home/hodei/anaconda3/envs/molmap/lib/python3.6/site-packages/tensorflow/__init__.py\", line 50, in __getattr__\n",
      "    module = self._load()\n",
      "  File \"/home/hodei/anaconda3/envs/molmap/lib/python3.6/site-packages/tensorflow/__init__.py\", line 44, in _load\n",
      "    module = _importlib.import_module(self.__name__)\n",
      "  File \"/home/hodei/anaconda3/envs/molmap/lib/python3.6/importlib/__init__.py\", line 126, in import_module\n",
      "    return _bootstrap._gcd_import(name[level:], package, level)\n",
      "  File \"<frozen importlib._bootstrap>\", line 994, in _gcd_import\n",
      "  File \"<frozen importlib._bootstrap>\", line 971, in _find_and_load\n",
      "  File \"<frozen importlib._bootstrap>\", line 953, in _find_and_load_unlocked\n",
      "ModuleNotFoundError: No module named 'tensorflow_core.estimator'\n",
      "ERROR! Session/line number was not unique in database. History logging moved to new session 3564\n",
      "Traceback (most recent call last):\n",
      "  File \"/home/hodei/anaconda3/envs/molmap/lib/python3.6/site-packages/IPython/core/interactiveshell.py\", line 3343, in run_code\n",
      "    exec(code_obj, self.user_global_ns, self.user_ns)\n",
      "  File \"<ipython-input-7-1883fbc42122>\", line 1, in <module>\n",
      "    auc = clf.score(testX, testY)\n",
      "  File \"/home/nuriacami/Documents/bidd-molmap/molmap/model/model.py\", line 544, in score\n",
      "    metrics = self._performance.evaluate(X, y)\n",
      "AttributeError: 'MultiClassEstimator' object has no attribute '_performance'\n",
      "\n",
      "During handling of the above exception, another exception occurred:\n",
      "\n",
      "Traceback (most recent call last):\n",
      "  File \"/home/hodei/anaconda3/envs/molmap/lib/python3.6/site-packages/IPython/core/interactiveshell.py\", line 2044, in showtraceback\n",
      "    stb = value._render_traceback_()\n",
      "AttributeError: 'AttributeError' object has no attribute '_render_traceback_'\n",
      "\n",
      "During handling of the above exception, another exception occurred:\n",
      "\n",
      "Traceback (most recent call last):\n",
      "  File \"/home/hodei/anaconda3/envs/molmap/lib/python3.6/site-packages/IPython/core/interactiveshell.py\", line 3263, in run_ast_nodes\n",
      "    if (await self.run_code(code, result,  async_=asy)):\n",
      "  File \"/home/hodei/anaconda3/envs/molmap/lib/python3.6/site-packages/IPython/core/interactiveshell.py\", line 3360, in run_code\n",
      "    self.showtraceback(running_compiled_code=True)\n",
      "  File \"/home/hodei/anaconda3/envs/molmap/lib/python3.6/site-packages/IPython/core/interactiveshell.py\", line 2047, in showtraceback\n",
      "    value, tb, tb_offset=tb_offset)\n",
      "  File \"/home/hodei/anaconda3/envs/molmap/lib/python3.6/site-packages/IPython/core/ultratb.py\", line 1436, in structured_traceback\n",
      "    self, etype, value, tb, tb_offset, number_of_lines_of_context)\n",
      "  File \"/home/hodei/anaconda3/envs/molmap/lib/python3.6/site-packages/IPython/core/ultratb.py\", line 1336, in structured_traceback\n",
      "    self, etype, value, tb, tb_offset, number_of_lines_of_context\n",
      "  File \"/home/hodei/anaconda3/envs/molmap/lib/python3.6/site-packages/IPython/core/ultratb.py\", line 1193, in structured_traceback\n",
      "    tb_offset)\n",
      "  File \"/home/hodei/anaconda3/envs/molmap/lib/python3.6/site-packages/IPython/core/ultratb.py\", line 1150, in format_exception_as_a_whole\n",
      "    last_unique, recursion_repeat = find_recursion(orig_etype, evalue, records)\n",
      "  File \"/home/hodei/anaconda3/envs/molmap/lib/python3.6/site-packages/IPython/core/ultratb.py\", line 451, in find_recursion\n",
      "    return len(records), 0\n",
      "TypeError: object of type 'NoneType' has no len()\n",
      "\n",
      "During handling of the above exception, another exception occurred:\n",
      "\n",
      "Traceback (most recent call last):\n",
      "  File \"/home/hodei/anaconda3/envs/molmap/lib/python3.6/site-packages/IPython/core/interactiveshell.py\", line 2044, in showtraceback\n",
      "    stb = value._render_traceback_()\n",
      "AttributeError: 'TypeError' object has no attribute '_render_traceback_'\n",
      "\n",
      "During handling of the above exception, another exception occurred:\n",
      "\n",
      "Traceback (most recent call last):\n",
      "  File \"/home/hodei/anaconda3/envs/molmap/lib/python3.6/site-packages/IPython/core/ultratb.py\", line 1169, in get_records\n",
      "    return _fixed_getinnerframes(etb, number_of_lines_of_context, tb_offset)\n",
      "  File \"/home/hodei/anaconda3/envs/molmap/lib/python3.6/site-packages/IPython/core/ultratb.py\", line 316, in wrapped\n",
      "    return f(*args, **kwargs)\n",
      "  File \"/home/hodei/anaconda3/envs/molmap/lib/python3.6/site-packages/IPython/core/ultratb.py\", line 350, in _fixed_getinnerframes\n",
      "    records = fix_frame_records_filenames(inspect.getinnerframes(etb, context))\n",
      "  File \"/home/hodei/anaconda3/envs/molmap/lib/python3.6/inspect.py\", line 1490, in getinnerframes\n",
      "    frameinfo = (tb.tb_frame,) + getframeinfo(tb, context)\n",
      "  File \"/home/hodei/anaconda3/envs/molmap/lib/python3.6/inspect.py\", line 1448, in getframeinfo\n",
      "    filename = getsourcefile(frame) or getfile(frame)\n",
      "  File \"/home/hodei/anaconda3/envs/molmap/lib/python3.6/inspect.py\", line 696, in getsourcefile\n",
      "    if getattr(getmodule(object, filename), '__loader__', None) is not None:\n",
      "  File \"/home/hodei/anaconda3/envs/molmap/lib/python3.6/inspect.py\", line 733, in getmodule\n",
      "    if ismodule(module) and hasattr(module, '__file__'):\n",
      "  File \"/home/hodei/anaconda3/envs/molmap/lib/python3.6/site-packages/tensorflow/__init__.py\", line 50, in __getattr__\n",
      "    module = self._load()\n",
      "  File \"/home/hodei/anaconda3/envs/molmap/lib/python3.6/site-packages/tensorflow/__init__.py\", line 44, in _load\n",
      "    module = _importlib.import_module(self.__name__)\n",
      "  File \"/home/hodei/anaconda3/envs/molmap/lib/python3.6/importlib/__init__.py\", line 126, in import_module\n",
      "    return _bootstrap._gcd_import(name[level:], package, level)\n",
      "  File \"<frozen importlib._bootstrap>\", line 994, in _gcd_import\n",
      "  File \"<frozen importlib._bootstrap>\", line 971, in _find_and_load\n",
      "  File \"<frozen importlib._bootstrap>\", line 953, in _find_and_load_unlocked\n",
      "ModuleNotFoundError: No module named 'tensorflow_core.estimator'\n",
      "Traceback (most recent call last):\n",
      "  File \"/home/hodei/anaconda3/envs/molmap/lib/python3.6/site-packages/IPython/core/interactiveshell.py\", line 3343, in run_code\n",
      "    exec(code_obj, self.user_global_ns, self.user_ns)\n",
      "  File \"<ipython-input-7-1883fbc42122>\", line 1, in <module>\n",
      "    auc = clf.score(testX, testY)\n",
      "  File \"/home/nuriacami/Documents/bidd-molmap/molmap/model/model.py\", line 544, in score\n",
      "    metrics = self._performance.evaluate(X, y)\n",
      "AttributeError: 'MultiClassEstimator' object has no attribute '_performance'\n",
      "\n",
      "During handling of the above exception, another exception occurred:\n",
      "\n",
      "Traceback (most recent call last):\n",
      "  File \"/home/hodei/anaconda3/envs/molmap/lib/python3.6/site-packages/IPython/core/interactiveshell.py\", line 2044, in showtraceback\n",
      "    stb = value._render_traceback_()\n",
      "AttributeError: 'AttributeError' object has no attribute '_render_traceback_'\n",
      "\n",
      "During handling of the above exception, another exception occurred:\n",
      "\n",
      "Traceback (most recent call last):\n",
      "  File \"/home/hodei/anaconda3/envs/molmap/lib/python3.6/site-packages/IPython/core/interactiveshell.py\", line 3263, in run_ast_nodes\n",
      "    if (await self.run_code(code, result,  async_=asy)):\n",
      "  File \"/home/hodei/anaconda3/envs/molmap/lib/python3.6/site-packages/IPython/core/interactiveshell.py\", line 3360, in run_code\n",
      "    self.showtraceback(running_compiled_code=True)\n",
      "  File \"/home/hodei/anaconda3/envs/molmap/lib/python3.6/site-packages/IPython/core/interactiveshell.py\", line 2047, in showtraceback\n",
      "    value, tb, tb_offset=tb_offset)\n",
      "  File \"/home/hodei/anaconda3/envs/molmap/lib/python3.6/site-packages/IPython/core/ultratb.py\", line 1436, in structured_traceback\n",
      "    self, etype, value, tb, tb_offset, number_of_lines_of_context)\n",
      "  File \"/home/hodei/anaconda3/envs/molmap/lib/python3.6/site-packages/IPython/core/ultratb.py\", line 1336, in structured_traceback\n",
      "    self, etype, value, tb, tb_offset, number_of_lines_of_context\n",
      "  File \"/home/hodei/anaconda3/envs/molmap/lib/python3.6/site-packages/IPython/core/ultratb.py\", line 1193, in structured_traceback\n",
      "    tb_offset)\n",
      "  File \"/home/hodei/anaconda3/envs/molmap/lib/python3.6/site-packages/IPython/core/ultratb.py\", line 1150, in format_exception_as_a_whole\n",
      "    last_unique, recursion_repeat = find_recursion(orig_etype, evalue, records)\n",
      "  File \"/home/hodei/anaconda3/envs/molmap/lib/python3.6/site-packages/IPython/core/ultratb.py\", line 451, in find_recursion\n",
      "    return len(records), 0\n",
      "TypeError: object of type 'NoneType' has no len()\n",
      "\n",
      "During handling of the above exception, another exception occurred:\n",
      "\n",
      "Traceback (most recent call last):\n",
      "  File \"/home/hodei/anaconda3/envs/molmap/lib/python3.6/site-packages/IPython/core/interactiveshell.py\", line 2044, in showtraceback\n",
      "    stb = value._render_traceback_()\n",
      "AttributeError: 'TypeError' object has no attribute '_render_traceback_'\n",
      "\n",
      "During handling of the above exception, another exception occurred:\n",
      "\n",
      "Traceback (most recent call last):\n",
      "  File \"/home/hodei/anaconda3/envs/molmap/lib/python3.6/site-packages/IPython/core/interactiveshell.py\", line 2895, in _run_cell\n",
      "    return runner(coro)\n",
      "  File \"/home/hodei/anaconda3/envs/molmap/lib/python3.6/site-packages/IPython/core/async_helpers.py\", line 68, in _pseudo_sync_runner\n",
      "    coro.send(None)\n",
      "  File \"/home/hodei/anaconda3/envs/molmap/lib/python3.6/site-packages/IPython/core/interactiveshell.py\", line 3072, in run_cell_async\n",
      "    interactivity=interactivity, compiler=compiler, result=result)\n",
      "  File \"/home/hodei/anaconda3/envs/molmap/lib/python3.6/site-packages/IPython/core/interactiveshell.py\", line 3282, in run_ast_nodes\n",
      "    self.showtraceback()\n",
      "  File \"/home/hodei/anaconda3/envs/molmap/lib/python3.6/site-packages/IPython/core/interactiveshell.py\", line 2047, in showtraceback\n",
      "    value, tb, tb_offset=tb_offset)\n",
      "  File \"/home/hodei/anaconda3/envs/molmap/lib/python3.6/site-packages/IPython/core/ultratb.py\", line 1436, in structured_traceback\n",
      "    self, etype, value, tb, tb_offset, number_of_lines_of_context)\n",
      "  File \"/home/hodei/anaconda3/envs/molmap/lib/python3.6/site-packages/IPython/core/ultratb.py\", line 1336, in structured_traceback\n",
      "    self, etype, value, tb, tb_offset, number_of_lines_of_context\n",
      "  File \"/home/hodei/anaconda3/envs/molmap/lib/python3.6/site-packages/IPython/core/ultratb.py\", line 1211, in structured_traceback\n",
      "    chained_exceptions_tb_offset)\n",
      "  File \"/home/hodei/anaconda3/envs/molmap/lib/python3.6/site-packages/IPython/core/ultratb.py\", line 1150, in format_exception_as_a_whole\n",
      "    last_unique, recursion_repeat = find_recursion(orig_etype, evalue, records)\n",
      "  File \"/home/hodei/anaconda3/envs/molmap/lib/python3.6/site-packages/IPython/core/ultratb.py\", line 451, in find_recursion\n",
      "    return len(records), 0\n",
      "TypeError: object of type 'NoneType' has no len()\n",
      "\n",
      "During handling of the above exception, another exception occurred:\n",
      "\n",
      "Traceback (most recent call last):\n",
      "  File \"/home/hodei/anaconda3/envs/molmap/lib/python3.6/site-packages/IPython/core/interactiveshell.py\", line 2044, in showtraceback\n",
      "    stb = value._render_traceback_()\n",
      "AttributeError: 'TypeError' object has no attribute '_render_traceback_'\n",
      "\n",
      "During handling of the above exception, another exception occurred:\n",
      "\n",
      "Traceback (most recent call last):\n",
      "  File \"/home/hodei/anaconda3/envs/molmap/lib/python3.6/site-packages/IPython/core/ultratb.py\", line 1169, in get_records\n",
      "    return _fixed_getinnerframes(etb, number_of_lines_of_context, tb_offset)\n",
      "  File \"/home/hodei/anaconda3/envs/molmap/lib/python3.6/site-packages/IPython/core/ultratb.py\", line 316, in wrapped\n",
      "    return f(*args, **kwargs)\n",
      "  File \"/home/hodei/anaconda3/envs/molmap/lib/python3.6/site-packages/IPython/core/ultratb.py\", line 350, in _fixed_getinnerframes\n",
      "    records = fix_frame_records_filenames(inspect.getinnerframes(etb, context))\n",
      "  File \"/home/hodei/anaconda3/envs/molmap/lib/python3.6/inspect.py\", line 1490, in getinnerframes\n",
      "    frameinfo = (tb.tb_frame,) + getframeinfo(tb, context)\n",
      "  File \"/home/hodei/anaconda3/envs/molmap/lib/python3.6/inspect.py\", line 1448, in getframeinfo\n",
      "    filename = getsourcefile(frame) or getfile(frame)\n",
      "  File \"/home/hodei/anaconda3/envs/molmap/lib/python3.6/inspect.py\", line 696, in getsourcefile\n",
      "    if getattr(getmodule(object, filename), '__loader__', None) is not None:\n",
      "  File \"/home/hodei/anaconda3/envs/molmap/lib/python3.6/inspect.py\", line 733, in getmodule\n",
      "    if ismodule(module) and hasattr(module, '__file__'):\n",
      "  File \"/home/hodei/anaconda3/envs/molmap/lib/python3.6/site-packages/tensorflow/__init__.py\", line 50, in __getattr__\n",
      "    module = self._load()\n",
      "  File \"/home/hodei/anaconda3/envs/molmap/lib/python3.6/site-packages/tensorflow/__init__.py\", line 44, in _load\n",
      "    module = _importlib.import_module(self.__name__)\n",
      "  File \"/home/hodei/anaconda3/envs/molmap/lib/python3.6/importlib/__init__.py\", line 126, in import_module\n",
      "    return _bootstrap._gcd_import(name[level:], package, level)\n",
      "  File \"<frozen importlib._bootstrap>\", line 994, in _gcd_import\n",
      "  File \"<frozen importlib._bootstrap>\", line 971, in _find_and_load\n",
      "  File \"<frozen importlib._bootstrap>\", line 953, in _find_and_load_unlocked\n",
      "ModuleNotFoundError: No module named 'tensorflow_core.estimator'\n"
     ]
    }
   ],
   "source": [
    "auc = clf.score(testX, testY) \n",
    "print(round(auc,3))"
   ]
  },
  {
   "cell_type": "code",
   "execution_count": null,
   "metadata": {},
   "outputs": [
    {
     "name": "stderr",
     "output_type": "stream",
     "text": [
      "ERROR:root:Internal Python error in the inspect module.\n",
      "Below is the traceback from this internal error.\n",
      "\n",
      "ERROR:root:Internal Python error in the inspect module.\n",
      "Below is the traceback from this internal error.\n",
      "\n"
     ]
    },
    {
     "name": "stdout",
     "output_type": "stream",
     "text": [
      "Traceback (most recent call last):\n",
      "  File \"/home/hodei/anaconda3/envs/molmap/lib/python3.6/site-packages/IPython/core/interactiveshell.py\", line 3343, in run_code\n",
      "    exec(code_obj, self.user_global_ns, self.user_ns)\n",
      "  File \"<ipython-input-7-03764d4df39a>\", line 4, in <module>\n",
      "    fpr, tpr, threshold = metrics.roc_curve(df_pred['y_true'], df_pred['y_pred_prob'])\n",
      "NameError: name 'df_pred' is not defined\n",
      "\n",
      "During handling of the above exception, another exception occurred:\n",
      "\n",
      "Traceback (most recent call last):\n",
      "  File \"/home/hodei/anaconda3/envs/molmap/lib/python3.6/site-packages/IPython/core/interactiveshell.py\", line 2044, in showtraceback\n",
      "    stb = value._render_traceback_()\n",
      "AttributeError: 'NameError' object has no attribute '_render_traceback_'\n",
      "\n",
      "During handling of the above exception, another exception occurred:\n",
      "\n",
      "Traceback (most recent call last):\n",
      "  File \"/home/hodei/anaconda3/envs/molmap/lib/python3.6/site-packages/IPython/core/ultratb.py\", line 1169, in get_records\n",
      "    return _fixed_getinnerframes(etb, number_of_lines_of_context, tb_offset)\n",
      "  File \"/home/hodei/anaconda3/envs/molmap/lib/python3.6/site-packages/IPython/core/ultratb.py\", line 316, in wrapped\n",
      "    return f(*args, **kwargs)\n",
      "  File \"/home/hodei/anaconda3/envs/molmap/lib/python3.6/site-packages/IPython/core/ultratb.py\", line 350, in _fixed_getinnerframes\n",
      "    records = fix_frame_records_filenames(inspect.getinnerframes(etb, context))\n",
      "  File \"/home/hodei/anaconda3/envs/molmap/lib/python3.6/inspect.py\", line 1490, in getinnerframes\n",
      "    frameinfo = (tb.tb_frame,) + getframeinfo(tb, context)\n",
      "  File \"/home/hodei/anaconda3/envs/molmap/lib/python3.6/inspect.py\", line 1448, in getframeinfo\n",
      "    filename = getsourcefile(frame) or getfile(frame)\n",
      "  File \"/home/hodei/anaconda3/envs/molmap/lib/python3.6/inspect.py\", line 696, in getsourcefile\n",
      "    if getattr(getmodule(object, filename), '__loader__', None) is not None:\n",
      "  File \"/home/hodei/anaconda3/envs/molmap/lib/python3.6/inspect.py\", line 733, in getmodule\n",
      "    if ismodule(module) and hasattr(module, '__file__'):\n",
      "  File \"/home/hodei/anaconda3/envs/molmap/lib/python3.6/site-packages/tensorflow/__init__.py\", line 50, in __getattr__\n",
      "    module = self._load()\n",
      "  File \"/home/hodei/anaconda3/envs/molmap/lib/python3.6/site-packages/tensorflow/__init__.py\", line 44, in _load\n",
      "    module = _importlib.import_module(self.__name__)\n",
      "  File \"/home/hodei/anaconda3/envs/molmap/lib/python3.6/importlib/__init__.py\", line 126, in import_module\n",
      "    return _bootstrap._gcd_import(name[level:], package, level)\n",
      "  File \"<frozen importlib._bootstrap>\", line 994, in _gcd_import\n",
      "  File \"<frozen importlib._bootstrap>\", line 971, in _find_and_load\n",
      "  File \"<frozen importlib._bootstrap>\", line 953, in _find_and_load_unlocked\n",
      "ModuleNotFoundError: No module named 'tensorflow_core.estimator'\n",
      "ERROR! Session/line number was not unique in database. History logging moved to new session 3565\n",
      "Traceback (most recent call last):\n",
      "  File \"/home/hodei/anaconda3/envs/molmap/lib/python3.6/site-packages/IPython/core/interactiveshell.py\", line 3343, in run_code\n",
      "    exec(code_obj, self.user_global_ns, self.user_ns)\n",
      "  File \"<ipython-input-7-03764d4df39a>\", line 4, in <module>\n",
      "    fpr, tpr, threshold = metrics.roc_curve(df_pred['y_true'], df_pred['y_pred_prob'])\n",
      "NameError: name 'df_pred' is not defined\n",
      "\n",
      "During handling of the above exception, another exception occurred:\n",
      "\n",
      "Traceback (most recent call last):\n",
      "  File \"/home/hodei/anaconda3/envs/molmap/lib/python3.6/site-packages/IPython/core/interactiveshell.py\", line 2044, in showtraceback\n",
      "    stb = value._render_traceback_()\n"
     ]
    },
    {
     "name": "stderr",
     "output_type": "stream",
     "text": [
      "ERROR:root:Internal Python error in the inspect module.\n",
      "Below is the traceback from this internal error.\n",
      "\n"
     ]
    },
    {
     "name": "stdout",
     "output_type": "stream",
     "text": [
      "AttributeError: 'NameError' object has no attribute '_render_traceback_'\n",
      "\n",
      "During handling of the above exception, another exception occurred:\n",
      "\n",
      "Traceback (most recent call last):\n",
      "  File \"/home/hodei/anaconda3/envs/molmap/lib/python3.6/site-packages/IPython/core/interactiveshell.py\", line 3263, in run_ast_nodes\n",
      "    if (await self.run_code(code, result,  async_=asy)):\n",
      "  File \"/home/hodei/anaconda3/envs/molmap/lib/python3.6/site-packages/IPython/core/interactiveshell.py\", line 3360, in run_code\n",
      "    self.showtraceback(running_compiled_code=True)\n",
      "  File \"/home/hodei/anaconda3/envs/molmap/lib/python3.6/site-packages/IPython/core/interactiveshell.py\", line 2047, in showtraceback\n",
      "    value, tb, tb_offset=tb_offset)\n",
      "  File \"/home/hodei/anaconda3/envs/molmap/lib/python3.6/site-packages/IPython/core/ultratb.py\", line 1436, in structured_traceback\n",
      "    self, etype, value, tb, tb_offset, number_of_lines_of_context)\n",
      "  File \"/home/hodei/anaconda3/envs/molmap/lib/python3.6/site-packages/IPython/core/ultratb.py\", line 1336, in structured_traceback\n",
      "    self, etype, value, tb, tb_offset, number_of_lines_of_context\n",
      "  File \"/home/hodei/anaconda3/envs/molmap/lib/python3.6/site-packages/IPython/core/ultratb.py\", line 1193, in structured_traceback\n",
      "    tb_offset)\n",
      "  File \"/home/hodei/anaconda3/envs/molmap/lib/python3.6/site-packages/IPython/core/ultratb.py\", line 1150, in format_exception_as_a_whole\n",
      "    last_unique, recursion_repeat = find_recursion(orig_etype, evalue, records)\n",
      "  File \"/home/hodei/anaconda3/envs/molmap/lib/python3.6/site-packages/IPython/core/ultratb.py\", line 451, in find_recursion\n",
      "    return len(records), 0\n",
      "TypeError: object of type 'NoneType' has no len()\n",
      "\n",
      "During handling of the above exception, another exception occurred:\n",
      "\n",
      "Traceback (most recent call last):\n",
      "  File \"/home/hodei/anaconda3/envs/molmap/lib/python3.6/site-packages/IPython/core/interactiveshell.py\", line 2044, in showtraceback\n",
      "    stb = value._render_traceback_()\n",
      "AttributeError: 'TypeError' object has no attribute '_render_traceback_'\n",
      "\n",
      "During handling of the above exception, another exception occurred:\n",
      "\n",
      "Traceback (most recent call last):\n",
      "  File \"/home/hodei/anaconda3/envs/molmap/lib/python3.6/site-packages/IPython/core/ultratb.py\", line 1169, in get_records\n",
      "    return _fixed_getinnerframes(etb, number_of_lines_of_context, tb_offset)\n",
      "  File \"/home/hodei/anaconda3/envs/molmap/lib/python3.6/site-packages/IPython/core/ultratb.py\", line 316, in wrapped\n",
      "    return f(*args, **kwargs)\n",
      "  File \"/home/hodei/anaconda3/envs/molmap/lib/python3.6/site-packages/IPython/core/ultratb.py\", line 350, in _fixed_getinnerframes\n",
      "    records = fix_frame_records_filenames(inspect.getinnerframes(etb, context))\n",
      "  File \"/home/hodei/anaconda3/envs/molmap/lib/python3.6/inspect.py\", line 1490, in getinnerframes\n",
      "    frameinfo = (tb.tb_frame,) + getframeinfo(tb, context)\n",
      "  File \"/home/hodei/anaconda3/envs/molmap/lib/python3.6/inspect.py\", line 1448, in getframeinfo\n",
      "    filename = getsourcefile(frame) or getfile(frame)\n",
      "  File \"/home/hodei/anaconda3/envs/molmap/lib/python3.6/inspect.py\", line 696, in getsourcefile\n",
      "    if getattr(getmodule(object, filename), '__loader__', None) is not None:\n",
      "  File \"/home/hodei/anaconda3/envs/molmap/lib/python3.6/inspect.py\", line 733, in getmodule\n",
      "    if ismodule(module) and hasattr(module, '__file__'):\n",
      "  File \"/home/hodei/anaconda3/envs/molmap/lib/python3.6/site-packages/tensorflow/__init__.py\", line 50, in __getattr__\n",
      "    module = self._load()\n",
      "  File \"/home/hodei/anaconda3/envs/molmap/lib/python3.6/site-packages/tensorflow/__init__.py\", line 44, in _load\n",
      "    module = _importlib.import_module(self.__name__)\n",
      "  File \"/home/hodei/anaconda3/envs/molmap/lib/python3.6/importlib/__init__.py\", line 126, in import_module\n",
      "    return _bootstrap._gcd_import(name[level:], package, level)\n",
      "  File \"<frozen importlib._bootstrap>\", line 994, in _gcd_import\n",
      "  File \"<frozen importlib._bootstrap>\", line 971, in _find_and_load\n",
      "  File \"<frozen importlib._bootstrap>\", line 953, in _find_and_load_unlocked\n",
      "ModuleNotFoundError: No module named 'tensorflow_core.estimator'\n",
      "Traceback (most recent call last):\n",
      "  File \"/home/hodei/anaconda3/envs/molmap/lib/python3.6/site-packages/IPython/core/interactiveshell.py\", line 3343, in run_code\n",
      "    exec(code_obj, self.user_global_ns, self.user_ns)\n",
      "  File \"<ipython-input-7-03764d4df39a>\", line 4, in <module>\n",
      "    fpr, tpr, threshold = metrics.roc_curve(df_pred['y_true'], df_pred['y_pred_prob'])\n",
      "NameError: name 'df_pred' is not defined\n",
      "\n",
      "During handling of the above exception, another exception occurred:\n",
      "\n",
      "Traceback (most recent call last):\n",
      "  File \"/home/hodei/anaconda3/envs/molmap/lib/python3.6/site-packages/IPython/core/interactiveshell.py\", line 2044, in showtraceback\n",
      "    stb = value._render_traceback_()\n",
      "AttributeError: 'NameError' object has no attribute '_render_traceback_'\n",
      "\n",
      "During handling of the above exception, another exception occurred:\n",
      "\n",
      "Traceback (most recent call last):\n",
      "  File \"/home/hodei/anaconda3/envs/molmap/lib/python3.6/site-packages/IPython/core/interactiveshell.py\", line 3263, in run_ast_nodes\n",
      "    if (await self.run_code(code, result,  async_=asy)):\n",
      "  File \"/home/hodei/anaconda3/envs/molmap/lib/python3.6/site-packages/IPython/core/interactiveshell.py\", line 3360, in run_code\n",
      "    self.showtraceback(running_compiled_code=True)\n",
      "  File \"/home/hodei/anaconda3/envs/molmap/lib/python3.6/site-packages/IPython/core/interactiveshell.py\", line 2047, in showtraceback\n",
      "    value, tb, tb_offset=tb_offset)\n",
      "  File \"/home/hodei/anaconda3/envs/molmap/lib/python3.6/site-packages/IPython/core/ultratb.py\", line 1436, in structured_traceback\n",
      "    self, etype, value, tb, tb_offset, number_of_lines_of_context)\n",
      "  File \"/home/hodei/anaconda3/envs/molmap/lib/python3.6/site-packages/IPython/core/ultratb.py\", line 1336, in structured_traceback\n",
      "    self, etype, value, tb, tb_offset, number_of_lines_of_context\n",
      "  File \"/home/hodei/anaconda3/envs/molmap/lib/python3.6/site-packages/IPython/core/ultratb.py\", line 1193, in structured_traceback\n",
      "    tb_offset)\n",
      "  File \"/home/hodei/anaconda3/envs/molmap/lib/python3.6/site-packages/IPython/core/ultratb.py\", line 1150, in format_exception_as_a_whole\n",
      "    last_unique, recursion_repeat = find_recursion(orig_etype, evalue, records)\n",
      "  File \"/home/hodei/anaconda3/envs/molmap/lib/python3.6/site-packages/IPython/core/ultratb.py\", line 451, in find_recursion\n",
      "    return len(records), 0\n",
      "TypeError: object of type 'NoneType' has no len()\n",
      "\n",
      "During handling of the above exception, another exception occurred:\n",
      "\n",
      "Traceback (most recent call last):\n",
      "  File \"/home/hodei/anaconda3/envs/molmap/lib/python3.6/site-packages/IPython/core/interactiveshell.py\", line 2044, in showtraceback\n",
      "    stb = value._render_traceback_()\n",
      "AttributeError: 'TypeError' object has no attribute '_render_traceback_'\n",
      "\n",
      "During handling of the above exception, another exception occurred:\n",
      "\n",
      "Traceback (most recent call last):\n",
      "  File \"/home/hodei/anaconda3/envs/molmap/lib/python3.6/site-packages/IPython/core/interactiveshell.py\", line 2895, in _run_cell\n",
      "    return runner(coro)\n",
      "  File \"/home/hodei/anaconda3/envs/molmap/lib/python3.6/site-packages/IPython/core/async_helpers.py\", line 68, in _pseudo_sync_runner\n",
      "    coro.send(None)\n",
      "  File \"/home/hodei/anaconda3/envs/molmap/lib/python3.6/site-packages/IPython/core/interactiveshell.py\", line 3072, in run_cell_async\n",
      "    interactivity=interactivity, compiler=compiler, result=result)\n",
      "  File \"/home/hodei/anaconda3/envs/molmap/lib/python3.6/site-packages/IPython/core/interactiveshell.py\", line 3282, in run_ast_nodes\n",
      "    self.showtraceback()\n",
      "  File \"/home/hodei/anaconda3/envs/molmap/lib/python3.6/site-packages/IPython/core/interactiveshell.py\", line 2047, in showtraceback\n",
      "    value, tb, tb_offset=tb_offset)\n",
      "  File \"/home/hodei/anaconda3/envs/molmap/lib/python3.6/site-packages/IPython/core/ultratb.py\", line 1436, in structured_traceback\n",
      "    self, etype, value, tb, tb_offset, number_of_lines_of_context)\n",
      "  File \"/home/hodei/anaconda3/envs/molmap/lib/python3.6/site-packages/IPython/core/ultratb.py\", line 1336, in structured_traceback\n",
      "    self, etype, value, tb, tb_offset, number_of_lines_of_context\n",
      "  File \"/home/hodei/anaconda3/envs/molmap/lib/python3.6/site-packages/IPython/core/ultratb.py\", line 1211, in structured_traceback\n",
      "    chained_exceptions_tb_offset)\n",
      "  File \"/home/hodei/anaconda3/envs/molmap/lib/python3.6/site-packages/IPython/core/ultratb.py\", line 1150, in format_exception_as_a_whole\n",
      "    last_unique, recursion_repeat = find_recursion(orig_etype, evalue, records)\n",
      "  File \"/home/hodei/anaconda3/envs/molmap/lib/python3.6/site-packages/IPython/core/ultratb.py\", line 451, in find_recursion\n",
      "    return len(records), 0\n",
      "TypeError: object of type 'NoneType' has no len()\n",
      "\n",
      "During handling of the above exception, another exception occurred:\n",
      "\n",
      "Traceback (most recent call last):\n",
      "  File \"/home/hodei/anaconda3/envs/molmap/lib/python3.6/site-packages/IPython/core/interactiveshell.py\", line 2044, in showtraceback\n",
      "    stb = value._render_traceback_()\n",
      "AttributeError: 'TypeError' object has no attribute '_render_traceback_'\n",
      "\n",
      "During handling of the above exception, another exception occurred:\n",
      "\n",
      "Traceback (most recent call last):\n",
      "  File \"/home/hodei/anaconda3/envs/molmap/lib/python3.6/site-packages/IPython/core/ultratb.py\", line 1169, in get_records\n",
      "    return _fixed_getinnerframes(etb, number_of_lines_of_context, tb_offset)\n",
      "  File \"/home/hodei/anaconda3/envs/molmap/lib/python3.6/site-packages/IPython/core/ultratb.py\", line 316, in wrapped\n",
      "    return f(*args, **kwargs)\n",
      "  File \"/home/hodei/anaconda3/envs/molmap/lib/python3.6/site-packages/IPython/core/ultratb.py\", line 350, in _fixed_getinnerframes\n",
      "    records = fix_frame_records_filenames(inspect.getinnerframes(etb, context))\n",
      "  File \"/home/hodei/anaconda3/envs/molmap/lib/python3.6/inspect.py\", line 1490, in getinnerframes\n",
      "    frameinfo = (tb.tb_frame,) + getframeinfo(tb, context)\n",
      "  File \"/home/hodei/anaconda3/envs/molmap/lib/python3.6/inspect.py\", line 1448, in getframeinfo\n",
      "    filename = getsourcefile(frame) or getfile(frame)\n",
      "  File \"/home/hodei/anaconda3/envs/molmap/lib/python3.6/inspect.py\", line 696, in getsourcefile\n",
      "    if getattr(getmodule(object, filename), '__loader__', None) is not None:\n",
      "  File \"/home/hodei/anaconda3/envs/molmap/lib/python3.6/inspect.py\", line 733, in getmodule\n",
      "    if ismodule(module) and hasattr(module, '__file__'):\n",
      "  File \"/home/hodei/anaconda3/envs/molmap/lib/python3.6/site-packages/tensorflow/__init__.py\", line 50, in __getattr__\n",
      "    module = self._load()\n",
      "  File \"/home/hodei/anaconda3/envs/molmap/lib/python3.6/site-packages/tensorflow/__init__.py\", line 44, in _load\n",
      "    module = _importlib.import_module(self.__name__)\n",
      "  File \"/home/hodei/anaconda3/envs/molmap/lib/python3.6/importlib/__init__.py\", line 126, in import_module\n",
      "    return _bootstrap._gcd_import(name[level:], package, level)\n",
      "  File \"<frozen importlib._bootstrap>\", line 994, in _gcd_import\n",
      "  File \"<frozen importlib._bootstrap>\", line 971, in _find_and_load\n",
      "  File \"<frozen importlib._bootstrap>\", line 953, in _find_and_load_unlocked\n",
      "ModuleNotFoundError: No module named 'tensorflow_core.estimator'\n"
     ]
    }
   ],
   "source": [
    "from sklearn import metrics\n",
    "\n",
    "# ROC curve\n",
    "fpr, tpr, threshold = metrics.roc_curve(df_pred['y_true'], df_pred['y_pred_prob'])\n",
    "roc_auc = metrics.auc(fpr, tpr)\n",
    "\n",
    "plt.title('Receiver Operating Characteristic')\n",
    "plt.plot(fpr, tpr, 'b', label = 'AUC = %0.3f' % roc_auc)\n",
    "plt.legend(loc = 'lower right')\n",
    "plt.plot([0, 1], [0, 1],'r--')\n",
    "plt.xlim([0, 1])\n",
    "plt.ylim([0, 1])\n",
    "plt.ylabel('True Positive Rate')\n",
    "plt.xlabel('False Positive Rate')\n",
    "plt.show()"
   ]
  }
 ],
 "metadata": {
  "interpreter": {
   "hash": "4b953d02031940799c70de464297ad7062f1169bc628a7b2471c13167aae5287"
  },
  "kernelspec": {
   "display_name": "Python 3",
   "language": "python",
   "name": "python3"
  },
  "language_info": {
   "codemirror_mode": {
    "name": "ipython",
    "version": 3
   },
   "file_extension": ".py",
   "mimetype": "text/x-python",
   "name": "python",
   "nbconvert_exporter": "python",
   "pygments_lexer": "ipython3",
   "version": "3.6.15"
  }
 },
 "nbformat": 4,
 "nbformat_minor": 4
}
